Workbook

Sheet 綜合總覽
A2: 瓏昇廠房新建工程｜三家報價比較
A3: 比較基準：使用者提供三份PDF。新臺幣元；未經同版圖說、範圍與規格校準。
A5: 比較指標 | B5: 大展營造 | C5: 立東營造 | D5: 基益營造 | E5: 判讀
A6: 原報價總額 | B6: =原報價總表!C6 -> 141502803 | C6: =原報價總表!C7 -> 143400000 | D6: =原報價總表!C8 -> 210047839 | E6: 各家原含稅總價，範圍不同，不是同範圍決標排名
A7: 稅前合計 | B7: =原報價總表!D6 -> 134764574 | C7: =原報價總表!D7 -> 136571429 | D7: =原報價總表!D8 -> 199983656 | E7: 基益空污費另列於稅後；大展稅前由總額扣原稅捐
A8: 原營業稅 | B8: =原報價總表!E6 -> 6738229 | C8: =原報價總表!E7 -> 6828571 | D8: =原報價總表!E8 -> 9999183 | E8: 原單列示稅額
A9: 空污費 | B9: =IF(原報價總表!F6="","未列價／業主負擔",原報價總表!F6) -> 未列價／業主負擔 | C9: =IF(原報價總表!F7="","未列價／業主負擔",原報價總表!F7) -> 未列價／業主負擔 | D9: =IF(原報價總表!F8="","未列價／業主負擔",原報價總表!F8) -> 65000 | E9: 未列價／業主負擔不可視為已含
A10: 比立東總價差額 | B10: =B6-$C$6 -> -1897197 | C10: =C6-$C$6 -> 0 | D10: =D6-$C$6 -> 66647839 | E10: 正數高於立東；負數低於立東
A11: 比立東總價差率 | B11: =B10/$C$6 -> -0.013230105 | C11: =C10/$C$6 -> 0 | D11: =D10/$C$6 -> 0.46476875 | E11: 差额÷立東原報價總額
A12: 報價日期 | B12: 2026-09-30 | C12: 2026-10-01 | D12: 2026-04-01 | E12: 立東依檔名；基益較其他兩家早約半年
A13: 電梯設備 | B13: 未含 | C13: 含客梯及貨梯 | D13: 含客梯及貨梯 | E13: 大展須另補價，不能直接以較低總價決標
A14: 原PDF頁數 | B14: 20 | C14: 9 | D14: 8 | E14: 大展頁首標示共41頁，但提供檔案20頁
A15: 未含項目含稅補價 | E15: 黃色欄可輸入已確認的補價；未填前不計調整後總額
A16: 補價後試算總額 | B16: =IF(B15="","待補價",B6+B15) -> 待補價 | C16: =IF(C15="","待補價",C6+C15) -> 待補價 | D16: =IF(D15="","待補價",D6+D15) -> 待補價 | E16: 僅補入自行填寫金額；仍不代表所有規格和數量一致
A19: 主要判讀
A20: 基益高價先查數量 | E20: 鋼筋983噸；大展348.11噸；立東297.83噸。優先確認圖說及計量範圍。
A21: 立東與大展價差較小 | E21: 但立東含電梯、大展不含；屋頂防水、EPOXY、玻璃及門窗規格不同。
A22: 乘算疑義 | E22: 基益兩筆防水複價比顯示乘算少134,450元；立東部分明細有小額精度差。 | G22: 廠商 | H22: 原報價總額
A23: 完整查閱 | E23: 分類比較涵蓋全部明細與費用；重點單價對照30項，未強行配對其餘不同工項。 | G23: =B5 -> 大展營造 | H23: =B6 -> 141502803
G24: =C5 -> 立東營造 | H24: =C6 -> 143400000
G25: =D5 -> 基益營造 | H25: =D6 -> 210047839

Sheet 分類比較
A2: 工程與費用分類比較（新臺幣元）
A3: 以工程功能粗分類，保留全部金額；同分類不代表同範圍、同規格。空白／未單列不視為零元。
A5: 統一比較分類 | B5: 大展營造 | C5: 立東營造 | D5: 基益營造 | E5: 立東減大展 | F5: 基益減立東 | G5: 比較限制
A6: 假設工程 | B6: =IF(COUNTIFS(三家明細!$O$6:$O$232,$A6)=0,"未單列",SUMIFS(三家明細!$I$6:$I$232,三家明細!$O$6:$O$232,$A6)) -> 3604928 | C6: =IF(COUNTIFS(三家明細!$O$233:$O$420,$A6)=0,"未單列",SUMIFS(三家明細!$I$233:$I$420,三家明細!$O$233:$O$420,$A6)) -> 3799609 | D6: =IF(COUNTIFS(三家明細!$O$421:$O$611,$A6)=0,"未單列",SUMIFS(三家明細!$I$421:$I$611,三家明細!$O$421:$O$611,$A6)) -> 6917256 | E6: =IF(AND(ISNUMBER(B6),ISNUMBER(C6)),C6-B6,"") -> 194681 | F6: =IF(AND(ISNUMBER(C6),ISNUMBER(D6)),D6-C6,"") -> 3117647 | G6: 費用歸類差異仍存在
A7: 土方及結構工程 | B7: =IF(COUNTIFS(三家明細!$O$6:$O$232,$A7)=0,"未單列",SUMIFS(三家明細!$I$6:$I$232,三家明細!$O$6:$O$232,$A7)) -> 39793568 | C7: =IF(COUNTIFS(三家明細!$O$233:$O$420,$A7)=0,"未單列",SUMIFS(三家明細!$I$233:$I$420,三家明細!$O$233:$O$420,$A7)) -> 37387686 | D7: =IF(COUNTIFS(三家明細!$O$421:$O$611,$A7)=0,"未單列",SUMIFS(三家明細!$I$421:$I$611,三家明細!$O$421:$O$611,$A7)) -> 63168038 | E7: =IF(AND(ISNUMBER(B7),ISNUMBER(C7)),C7-B7,"") -> -2405882 | F7: =IF(AND(ISNUMBER(C7),ISNUMBER(D7)),D7-C7,"") -> 25780352 | G7: 大展土方＋結構；另兩家結構已含土方
A8: 鋼構工程 | B8: =IF(COUNTIFS(三家明細!$O$6:$O$232,$A8)=0,"未單列",SUMIFS(三家明細!$I$6:$I$232,三家明細!$O$6:$O$232,$A8)) -> 31302484 | C8: =IF(COUNTIFS(三家明細!$O$233:$O$420,$A8)=0,"未單列",SUMIFS(三家明細!$I$233:$I$420,三家明細!$O$233:$O$420,$A8)) -> 35684599 | D8: =IF(COUNTIFS(三家明細!$O$421:$O$611,$A8)=0,"未單列",SUMIFS(三家明細!$I$421:$I$611,三家明細!$O$421:$O$611,$A8)) -> 41869118 | E8: =IF(AND(ISNUMBER(B8),ISNUMBER(C8)),C8-B8,"") -> 4382115 | F8: =IF(AND(ISNUMBER(C8),ISNUMBER(D8)),D8-C8,"") -> 6184519 | G8: 鋼材牌號、板厚及加工範圍不同
A9: 內外裝修及防水 | B9: =IF(COUNTIFS(三家明細!$O$6:$O$232,$A9)=0,"未單列",SUMIFS(三家明細!$I$6:$I$232,三家明細!$O$6:$O$232,$A9)) -> 32195141 | C9: =IF(COUNTIFS(三家明細!$O$233:$O$420,$A9)=0,"未單列",SUMIFS(三家明細!$I$233:$I$420,三家明細!$O$233:$O$420,$A9)) -> 29804181 | D9: =IF(COUNTIFS(三家明細!$O$421:$O$611,$A9)=0,"未單列",SUMIFS(三家明細!$I$421:$I$611,三家明細!$O$421:$O$611,$A9)) -> 54161082 | E9: =IF(AND(ISNUMBER(B9),ISNUMBER(C9)),C9-B9,"") -> -2390960 | F9: =IF(AND(ISNUMBER(C9),ISNUMBER(D9)),D9-C9,"") -> 24356901 | G9: 大展內外裝修；立東泥作；基益泥作＋外裝
A10: 門窗工程 | B10: =IF(COUNTIFS(三家明細!$O$6:$O$232,$A10)=0,"未單列",SUMIFS(三家明細!$I$6:$I$232,三家明細!$O$6:$O$232,$A10)) -> 7140806 | C10: =IF(COUNTIFS(三家明細!$O$233:$O$420,$A10)=0,"未單列",SUMIFS(三家明細!$I$233:$I$420,三家明細!$O$233:$O$420,$A10)) -> 9523700 | D10: =IF(COUNTIFS(三家明細!$O$421:$O$611,$A10)=0,"未單列",SUMIFS(三家明細!$I$421:$I$611,三家明細!$O$421:$O$611,$A10)) -> 7371886 | E10: =IF(AND(ISNUMBER(B10),ISNUMBER(C10)),C10-B10,"") -> 2382894 | F10: =IF(AND(ISNUMBER(C10),ISNUMBER(D10)),D10-C10,"") -> -2151814 | G10: 玻璃、填縫与五金內含方式不同
A11: 設備、雜項及室外 | B11: =IF(COUNTIFS(三家明細!$O$6:$O$232,$A11)=0,"未單列",SUMIFS(三家明細!$I$6:$I$232,三家明細!$O$6:$O$232,$A11)) -> 3810721 | C11: =IF(COUNTIFS(三家明細!$O$233:$O$420,$A11)=0,"未單列",SUMIFS(三家明細!$I$233:$I$420,三家明細!$O$233:$O$420,$A11)) -> 5789532 | D11: =IF(COUNTIFS(三家明細!$O$421:$O$611,$A11)=0,"未單列",SUMIFS(三家明細!$I$421:$I$611,三家明細!$O$421:$O$611,$A11)) -> 9480285 | E11: =IF(AND(ISNUMBER(B11),ISNUMBER(C11)),C11-B11,"") -> 1978811 | F11: =IF(AND(ISNUMBER(C11),ISNUMBER(D11)),D11-C11,"") -> 3690753 | G11: 設備、雜項、公共設施、景觀；大展不含電梯
A12: 運什、安衛及保險 | B12: =IF(COUNTIFS(三家明細!$O$6:$O$232,$A12)=0,"未單列",SUMIFS(三家明細!$I$6:$I$232,三家明細!$O$6:$O$232,$A12)) -> 3605864 | C12: =IF(COUNTIFS(三家明細!$O$233:$O$420,$A12)=0,"未單列",SUMIFS(三家明細!$I$233:$I$420,三家明細!$O$233:$O$420,$A12)) -> 2927743 | D12: =IF(COUNTIFS(三家明細!$O$421:$O$611,$A12)=0,"未單列",SUMIFS(三家明細!$I$421:$I$611,三家明細!$O$421:$O$611,$A12)) -> 2378579 | E12: =IF(AND(ISNUMBER(B12),ISNUMBER(C12)),C12-B12,"") -> -678121 | F12: =IF(AND(ISNUMBER(C12),ISNUMBER(D12)),D12-C12,"") -> -549164 | G12: 部分工地費用在假設工程或明細中，不能僅依費率比較
A13: 管理及利潤 | B13: =IF(COUNTIFS(三家明細!$O$6:$O$232,$A13)=0,"未單列",SUMIFS(三家明細!$I$6:$I$232,三家明細!$O$6:$O$232,$A13)) -> 13311062 | C13: =IF(COUNTIFS(三家明細!$O$233:$O$420,$A13)=0,"未單列",SUMIFS(三家明細!$I$233:$I$420,三家明細!$O$233:$O$420,$A13)) -> 11654379 | D13: =IF(COUNTIFS(三家明細!$O$421:$O$611,$A13)=0,"未單列",SUMIFS(三家明細!$I$421:$I$611,三家明細!$O$421:$O$611,$A13)) -> 14637413 | E13: =IF(AND(ISNUMBER(B13),ISNUMBER(C13)),C13-B13,"") -> -1656683 | F13: =IF(AND(ISNUMBER(C13),ISNUMBER(D13)),D13-C13,"") -> 2983034 | G13: 各家費用基礎與利潤內含方式不同
A14: 營業稅 | B14: =IF(COUNTIFS(三家明細!$O$6:$O$232,$A14)=0,"未單列",SUMIFS(三家明細!$I$6:$I$232,三家明細!$O$6:$O$232,$A14)) -> 6738229 | C14: =IF(COUNTIFS(三家明細!$O$233:$O$420,$A14)=0,"未單列",SUMIFS(三家明細!$I$233:$I$420,三家明細!$O$233:$O$420,$A14)) -> 6828571 | D14: =IF(COUNTIFS(三家明細!$O$421:$O$611,$A14)=0,"未單列",SUMIFS(三家明細!$I$421:$I$611,三家明細!$O$421:$O$611,$A14)) -> 9999183 | E14: =IF(AND(ISNUMBER(B14),ISNUMBER(C14)),C14-B14,"") -> 90342 | F14: =IF(AND(ISNUMBER(C14),ISNUMBER(D14)),D14-C14,"") -> 3170612 | G14: 依原報價稅額
A15: 空污費 | B15: =IF(COUNTIFS(三家明細!$O$6:$O$232,$A15)=0,"未單列",SUMIFS(三家明細!$I$6:$I$232,三家明細!$O$6:$O$232,$A15)) -> 未單列 | C15: =IF(COUNTIFS(三家明細!$O$233:$O$420,$A15)=0,"未單列",SUMIFS(三家明細!$I$233:$I$420,三家明細!$O$233:$O$420,$A15)) -> 未單列 | D15: =IF(COUNTIFS(三家明細!$O$421:$O$611,$A15)=0,"未單列",SUMIFS(三家明細!$I$421:$I$611,三家明細!$O$421:$O$611,$A15)) -> 65000 | E15: =IF(AND(ISNUMBER(B15),ISNUMBER(C15)),C15-B15,"") | F15: =IF(AND(ISNUMBER(C15),ISNUMBER(D15)),D15-C15,"") | G15: 僅基益有列價；其他為業主負擔
A17: 逐筆明細與費用總和 | B17: =SUM(B6:B15) -> 141502803 | C17: =SUM(C6:C15) -> 143400000 | D17: =SUM(D6:D15) -> 210047840
A18: 原報價總額 | B18: =綜合總覽!B6 -> 141502803 | C18: =綜合總覽!C6 -> 143400000 | D18: =綜合總覽!D6 -> 210047839
A19: 逐筆加總減原總額 | B19: =B17-B18 -> 0 | C19: =C17-C18 -> 0 | D19: =D17-D18 -> 1

Sheet 單價與數量
A2: 重點項目單價、數量與原複價
A3: 僅為相近工項對照，均須核規格；合併工項單價用數量加權。單價高低差率＝最高／最低－1，不代表可節省金額。
A5: 對照項目 | B5: 單位 | C5: 大展數量 | D5: 大展單價 | E5: 大展原複價 | F5: 立東數量 | G5: 立東單價 | H5: 立東原複價 | I5: 基益數量 | J5: 基益單價 | K5: 基益原複價 | L5: 單價高低差率 | M5: 比較限制 | N5: 來源明細ID
A6: 土方開挖 | B6: M3 | C6: =SUM(三家明細!G14) -> 1421.46 | D6: =三家明細!H14 -> 450 | E6: =SUM(三家明細!I14) -> 639657 | F6: =SUM(三家明細!G252) -> 1969 | G6: =三家明細!H252 -> 270 | H6: =SUM(三家明細!I252) -> 531630 | I6: =SUM(三家明細!G443) -> 4485 | J6: =三家明細!H443 -> 285 | K6: =SUM(三家明細!I443) -> 1278225 | L6: =IF(COUNT(D6,G6,J6)<3,"",MAX(D6,G6,J6)/MIN(D6,G6,J6)-1) -> 0.66666667 | M6: 深度、餘土及運棄範圍不同，需同版數量 | N6: dazhan-009、lidong-020、jiyi-023
A7: 回填土方 | B7: M3 | C7: =SUM(三家明細!G15) -> 1421.46 | D7: =三家明細!H15 -> 360 | E7: =SUM(三家明細!I15) -> 511726 | F7: =SUM(三家明細!G253) -> 1819 | G7: =三家明細!H253 -> 340 | H7: =SUM(三家明細!I253) -> 618460 | I7: =SUM(三家明細!G445) -> 3250 | J7: =三家明細!H445 -> 285 | K7: =SUM(三家明細!I445) -> 926250 | L7: =IF(COUNT(D7,G7,J7)<3,"",MAX(D7,G7,J7)/MIN(D7,G7,J7)-1) -> 0.26315789 | M7: 大展暫置基地內；另兩家夯實範圍需確認 | N7: dazhan-010、lidong-021、jiyi-025
A8: 2000PSI混凝土 | B8: M3 | C8: =SUM(三家明細!G44) -> 286.35 | D8: =三家明細!H44 -> 2940 | E8: =SUM(三家明細!I44) -> 841869 | F8: =SUM(三家明細!G258) -> 93 | G8: =三家明細!H258 -> 2870 | H8: =SUM(三家明細!I258) -> 266910 | I8: =SUM(三家明細!G444) -> 425 | J8: =三家明細!H444 -> 3000 | K8: =SUM(三家明細!I444) -> 1275000 | L8: =IF(COUNT(D8,G8,J8)<3,"",MAX(D8,G8,J8)/MIN(D8,G8,J8)-1) -> 0.045296167 | M8: 強度相近；品牌、配比及泵送條件待統一 | N8: dazhan-039、lidong-026、jiyi-024
A9: 4000PSI混凝土 | B9: M3 | C9: =SUM(三家明細!G45) -> 2747.47 | D9: =三家明細!H45 -> 3240 | E9: =SUM(三家明細!I45) -> 8901803 | F9: =SUM(三家明細!G259) -> 2568 | G9: =三家明細!H259 -> 3210 | H9: =SUM(三家明細!I259) -> 8243290 | I9: =SUM(三家明細!G450) -> 1795 | J9: =三家明細!H450 -> 3850 | K9: =SUM(三家明細!I450) -> 6910750 | L9: =IF(COUNT(D9,G9,J9)<3,"",MAX(D9,G9,J9)/MIN(D9,G9,J9)-1) -> 0.19937695 | M9: 強度相近；立東原複價有10元乘算差 | N9: dazhan-040、lidong-027、jiyi-030
A10: SD280鋼筋 | B10: 噸 | C10: =SUM(三家明細!G41) -> 96.04 | D10: =三家明細!H41 -> 27900 | E10: =SUM(三家明細!I41) -> 2679516 | F10: =SUM(三家明細!G256) -> 88.76 | G10: =三家明細!H256 -> 28300 | H10: =SUM(三家明細!I256) -> 2511908 | I10: =SUM(三家明細!G448) -> 648 | J10: =三家明細!H448 -> 30100 | K10: =SUM(三家明細!I448) -> 19504800 | L10: =IF(COUNT(D10,G10,J10)<3,"",MAX(D10,G10,J10)/MIN(D10,G10,J10)-1) -> 0.078853047 | M10: 鋼筋號數範圍不一致；僅作數量與單價線索 | N10: dazhan-036、lidong-024、jiyi-028
A11: SD420鋼筋 | B11: 噸 | C11: =SUM(三家明細!G42) -> 252.07 | D11: =三家明細!H42 -> 28700 | E11: =SUM(三家明細!I42) -> 7234409 | F11: =SUM(三家明細!G257) -> 209.07 | G11: =三家明細!H257 -> 29200 | H11: =SUM(三家明細!I257) -> 6104844 | I11: =SUM(三家明細!G449) -> 335 | J11: =三家明細!H449 -> 32000 | K11: =SUM(三家明細!I449) -> 10720000 | L11: =IF(COUNT(D11,G11,J11)<3,"",MAX(D11,G11,J11)/MIN(D11,G11,J11)-1) -> 0.11498258 | M11: 大展#4以上；基益#6–#11，號數範圍不一致 | N11: dazhan-037、lidong-025、jiyi-029
A12: 普通／系統模板 | B12: M2 | C12: =SUM(三家明細!G47) -> 12533.35 | D12: =三家明細!H47 -> 1050 | E12: =SUM(三家明細!I47) -> 13160018 | F12: =SUM(三家明細!G255) -> 12412 | G12: =三家明細!H255 -> 1170 | H12: =SUM(三家明細!I255) -> 14522040 | I12: =SUM(三家明細!G446,三家明細!G447) -> 12710 | J12: =(三家明細!G446*三家明細!H446+三家明細!G447*三家明細!H447)/I12 -> 1325.1967 | K12: =SUM(三家明細!I446,三家明細!I447) -> 16843250 | L12: =IF(COUNT(D12,G12,J12)<3,"",MAX(D12,G12,J12)/MIN(D12,G12,J12)-1) -> 0.26209209 | M12: 基益為兩種模板加權單價；面積與模板型式不同 | N12: dazhan-042、lidong-023、jiyi-026、jiyi-027
A13: EPOXY地坪 | B13: M2 | C13: =SUM(三家明細!G75) -> 2925.82 | D13: =三家明細!H75 -> 710 | E13: =SUM(三家明細!I75) -> 2077332 | F13: =SUM(三家明細!G302) -> 2854 | G13: =三家明細!H302 -> 1240 | H13: =SUM(三家明細!I302) -> 3538960 | I13: =SUM(三家明細!G493) -> 2925 | J13: =三家明細!H493 -> 1200 | K13: =SUM(三家明細!I493) -> 3510000 | L13: =IF(COUNT(D13,G13,J13)<3,"",MAX(D13,G13,J13)/MIN(D13,G13,J13)-1) -> 0.74647887 | M13: 大展3mm、立東5mm且含粉光；基益厚度未列 | N13: dazhan-070、lidong-070、jiyi-073
A14: 明架礦纖天花 | B14: M2 | C14: =SUM(三家明細!G91) -> 958.42 | D14: =三家明細!H91 -> 450 | E14: =SUM(三家明細!I91) -> 431289 | F14: =SUM(三家明細!G312) -> 937 | G14: =三家明細!H312 -> 570 | H14: =SUM(三家明細!I312) -> 534090 | I14: =SUM(三家明細!G509) -> 1205.05 | J14: =三家明細!H509 -> 950 | K14: =SUM(三家明細!I509) -> 1144798 | L14: =IF(COUNT(D14,G14,J14)<3,"",MAX(D14,G14,J14)/MIN(D14,G14,J14)-1) -> 1.1111111 | M14: 60×60；品牌、骨架及收邊待統一 | N14: dazhan-086、lidong-080、jiyi-089
A15: 暗架矽酸鈣天花 | B15: M2 | C15: =SUM(三家明細!G92) -> 119.17 | D15: =三家明細!H92 -> 1410 | E15: =SUM(三家明細!I92) -> 168030 | F15: =SUM(三家明細!G313) -> 177 | G15: =三家明細!H313 -> 1140 | H15: =SUM(三家明細!I313) -> 201780 | I15: =SUM(三家明細!G510) -> 122.69 | J15: =三家明細!H510 -> 3500 | K15: =SUM(三家明細!I510) -> 429415 | L15: =IF(COUNT(D15,G15,J15)<3,"",MAX(D15,G15,J15)/MIN(D15,G15,J15)-1) -> 2.0701754 | M15: 油漆、板厚與收邊內容不同 | N15: dazhan-087、lidong-081、jiyi-090
A16: 一般輕隔間 | B16: M2 | C16: =SUM(三家明細!G66) -> 1110.75 | D16: =三家明細!H66 -> 1450 | E16: =SUM(三家明細!I66) -> 1610588 | F16: =SUM(三家明細!G314) -> 1575 | G16: =三家明細!H314 -> 1190 | H16: =SUM(三家明細!I314) -> 1874250 | I16: =SUM(三家明細!G503) -> 3110.2 | J16: =三家明細!H503 -> 2500 | K16: =SUM(三家明細!I503) -> 7775500 | L16: =IF(COUNT(D16,G16,J16)<3,"",MAX(D16,G16,J16)/MIN(D16,G16,J16)-1) -> 1.1008403 | M16: 大展一般型；立東不含岩棉；基益10cm牆厚 | N16: dazhan-061、lidong-082、jiyi-083
A17: RC內牆粉光油漆 | B17: M2 | C17: =SUM(三家明細!G86) -> 3156.85 | D17: =三家明細!H86 -> 842 | E17: =SUM(三家明細!I86) -> 2658068 | F17: =SUM(三家明細!G315) -> 3870 | G17: =三家明細!H315 -> 770 | H17: =SUM(三家明細!I315) -> 2979900 | I17: =SUM(三家明細!G505) -> 6934.29 | J17: =三家明細!H505 -> 1450 | K17: =SUM(三家明細!I505) -> 10054721 | L17: =IF(COUNT(D17,G17,J17)<3,"",MAX(D17,G17,J17)/MIN(D17,G17,J17)-1) -> 0.88311688 | M17: 施作面積、塗料與分項範圍不同 | N17: dazhan-081、lidong-083、jiyi-085
A18: 輕隔間批土油漆 | B18: M2 | C18: =SUM(三家明細!G87) -> 2680.78 | D18: =三家明細!H87 -> 240 | E18: =SUM(三家明細!I87) -> 643387 | F18: =SUM(三家明細!G316) -> 2625 | G18: =三家明細!H316 -> 140 | H18: =SUM(三家明細!I316) -> 367500 | I18: =SUM(三家明細!G504) -> 2485.3 | J18: =三家明細!H504 -> 350 | K18: =SUM(三家明細!I504) -> 869855 | L18: =IF(COUNT(D18,G18,J18)<3,"",MAX(D18,G18,J18)/MIN(D18,G18,J18)-1) -> 1.5 | M18: 品牌與塗裝道數待核對 | N18: dazhan-082、lidong-084、jiyi-084
A19: 外牆二丁掛磚 | B19: M2 | C19: =SUM(三家明細!G105) -> 1988.62 | D19: =三家明細!H105 -> 1631 | E19: =SUM(三家明細!I105) -> 3243439 | F19: =SUM(三家明細!G321) -> 2427 | G19: =三家明細!H321 -> 1380 | H19: =SUM(三家明細!I321) -> 3349263 | I19: =SUM(三家明細!G512) -> 1072.5 | J19: =三家明細!H512 -> 2450 | K19: =SUM(三家明細!I512) -> 2627625 | L19: =IF(COUNT(D19,G19,J19)<3,"",MAX(D19,G19,J19)/MIN(D19,G19,J19)-1) -> 0.77536232 | M19: 磚款、基層及計量面積不同 | N19: dazhan-100、lidong-089、jiyi-092
A20: 外牆金屬包板 | B20: M2 | C20: =SUM(三家明細!G114) -> 358.44 | D20: =三家明細!H114 -> 8000 | E20: =SUM(三家明細!I114) -> 2867520 | F20: =SUM(三家明細!G322) -> 362 | G20: =三家明細!H322 -> 7420 | H20: =SUM(三家明細!I322) -> 2686040 | I20: =SUM(三家明細!G513) -> 945 | J20: =三家明細!H513 -> 6500 | K20: =SUM(三家明細!I513) -> 6142500 | L20: =IF(COUNT(D20,G20,J20)<3,"",MAX(D20,G20,J20)/MIN(D20,G20,J20)-1) -> 0.23076923 | M20: 大展2.5t鋁板含骨架；另兩家厚度待確認 | N20: dazhan-109、lidong-090、jiyi-093
A21: 仿清水模塗料 | B21: M2 | C21: =SUM(三家明細!G107) -> 289.12 | D21: =三家明細!H107 -> 1910 | E21: =SUM(三家明細!I107) -> 552219 | F21: =SUM(三家明細!G326) -> 247 | G21: =三家明細!H326 -> 1970 | H21: =SUM(三家明細!I326) -> 486590 | I21: =SUM(三家明細!G516) -> 261.82 | J21: =三家明細!H516 -> 2100 | K21: =SUM(三家明細!I516) -> 549822 | L21: =IF(COUNT(D21,G21,J21)<3,"",MAX(D21,G21,J21)/MIN(D21,G21,J21)-1) -> 0.09947644 | M21: 大展鈴鹿；立東國產；基益品牌未列 | N21: dazhan-102、lidong-094、jiyi-096
A22: 淺色外牆塗料 | B22: M2 | C22: =SUM(三家明細!G108) -> 660.54 | D22: =三家明細!H108 -> 1480 | E22: =SUM(三家明細!I108) -> 977599 | F22: =SUM(三家明細!G324) -> 730 | G22: =三家明細!H324 -> 1580 | H22: =SUM(三家明細!I324) -> 1153400 | I22: =SUM(三家明細!G517) -> 334.89 | J22: =三家明細!H517 -> 1850 | K22: =SUM(三家明細!I517) -> 619547 | L22: =IF(COUNT(D22,G22,J22)<3,"",MAX(D22,G22,J22)/MIN(D22,G22,J22)-1) -> 0.25 | M22: 品牌與工法不同 | N22: dazhan-103、lidong-092、jiyi-097
A23: 屋頂平台防水 | B23: M2 | C23: =SUM(三家明細!G100) -> 1686.01 | D23: =三家明細!H100 -> 1800 | E23: =SUM(三家明細!I100) -> 3034818 | F23: =SUM(三家明細!G296) -> 1889 | G23: =三家明細!H296 -> 880 | H23: =SUM(三家明細!I296) -> 1662322 | I23: =SUM(三家明細!G486) -> 1457.26 | J23: =三家明細!H486 -> 750 | K23: =SUM(三家明細!I486) -> 1092945 | L23: =IF(COUNT(D23,G23,J23)<3,"",MAX(D23,G23,J23)/MIN(D23,G23,J23)-1) -> 1.4 | M23: 聚脲／彈泥／未詳工法，不宜作同規格排名 | N23: dazhan-095、lidong-064、jiyi-066
A24: 客用無障礙電梯 | B24: 部 | C24: 未含 | D24: 未含 | E24: 未含 | F24: =SUM(三家明細!G380) -> 1 | G24: =三家明細!H380 -> 1243800 | H24: =SUM(三家明細!I380) -> 1243800 | I24: =SUM(三家明細!G578) -> 1 | J24: =三家明細!H578 -> 938000 | K24: =SUM(三家明細!I578) -> 938000 | L24: =IF(COUNT(D24,G24,J24)<3,"",MAX(D24,G24,J24)/MIN(D24,G24,J24)-1) | M24: 大展不含；立東立穩/國峰，基益小金井 | N24: lidong-148、jiyi-158
A25: 貨物電梯 | B25: 部 | C25: 未含 | D25: 未含 | E25: 未含 | F25: =SUM(三家明細!G381) -> 1 | G25: =三家明細!H381 -> 2448900 | H25: =SUM(三家明細!I381) -> 2448900 | I25: =SUM(三家明細!G579) -> 1 | J25: =三家明細!H579 -> 2580000 | K25: =SUM(三家明細!I579) -> 2580000 | L25: =IF(COUNT(D25,G25,J25)<3,"",MAX(D25,G25,J25)/MIN(D25,G25,J25)-1) | M25: 載重、停靠層、速度及品牌需統一 | N25: lidong-149、jiyi-159
A26: 污水處理設施 | B26: 座 | C26: =SUM(三家明細!G214) -> 2 | D26: =三家明細!H214 -> 60700 | E26: =SUM(三家明細!I214) -> 121400 | F26: =SUM(三家明細!G409) -> 2 | G26: =三家明細!H409 -> 64900 | H26: =SUM(三家明細!I409) -> 129800 | I26: =SUM(三家明細!G580) -> 2 | J26: =三家明細!H580 -> 150000 | K26: =SUM(三家明細!I580) -> 300000 | L26: =IF(COUNT(D26,G26,J26)<3,"",MAX(D26,G26,J26)/MIN(D26,G26,J26)-1) -> 1.4711697 | M26: 10人份；槽體保護與承裝範圍不同 | N26: dazhan-209、lidong-177、jiyi-160
A27: 廁所隔間含門 | B27: M2 | C27: =SUM(三家明細!G202) -> 71.4 | D27: =三家明細!H202 -> 3000 | E27: =SUM(三家明細!I202) -> 214200 | F27: =SUM(三家明細!G385) -> 78 | G27: =三家明細!H385 -> 2400 | H27: =SUM(三家明細!I385) -> 187200 | I27: =SUM(三家明細!G582) -> 71.19 | J27: =三家明細!H582 -> 4000 | K27: =SUM(三家明細!I582) -> 284760 | L27: =IF(COUNT(D27,G27,J27)<3,"",MAX(D27,G27,J27)/MIN(D27,G27,J27)-1) -> 0.66666667 | M27: 大展ABS H210；立東PVC H240；基益材質待確認 | N27: dazhan-197、lidong-153、jiyi-162
A28: 小便斗隔屏 | B28: 片／組 | C28: =SUM(三家明細!G203) -> 9 | D28: =三家明細!H203 -> 1700 | E28: =SUM(三家明細!I203) -> 15300 | F28: =SUM(三家明細!G386) -> 9 | G28: =三家明細!H386 -> 2500 | H28: =SUM(三家明細!I386) -> 22500 | I28: =SUM(三家明細!G583) -> 6 | J28: =三家明細!H583 -> 1500 | K28: =SUM(三家明細!I583) -> 9000 | L28: =IF(COUNT(D28,G28,J28)<3,"",MAX(D28,G28,J28)/MIN(D28,G28,J28)-1) -> 0.66666667 | M28: 尺寸及材質不同，單位片/組需確認 | N28: dazhan-198、lidong-154、jiyi-163
A29: 樓梯扶手 | B29: M | C29: =SUM(三家明細!G194) -> 143.4 | D29: =三家明細!H194 -> 1600 | E29: =SUM(三家明細!I194) -> 229440 | F29: =SUM(三家明細!G402) -> 118 | G29: =三家明細!H402 -> 1500 | H29: =SUM(三家明細!I402) -> 177000 | I29: =SUM(三家明細!G590,三家明細!G591) -> 110.02 | J29: =(三家明細!G590*三家明細!H590+三家明細!G591*三家明細!H591)/I29 -> 4500 | K29: =SUM(三家明細!I590,三家明細!I591) -> 495090 | L29: =IF(COUNT(D29,G29,J29)<3,"",MAX(D29,G29,J29)/MIN(D29,G29,J29)-1) -> 2 | M29: 大展實木、立東櫸木；基益立柱及扶壁式 | N29: dazhan-189、lidong-170、jiyi-170、jiyi-171
A30: SD1快速捲門 | B30: 樘 | C30: =SUM(三家明細!G156) -> 1 | D30: =三家明細!H156 -> 163500 | E30: =SUM(三家明細!I156) -> 163500 | F30: =SUM(三家明細!G357) -> 1 | G30: =三家明細!H357 -> 121900 | H30: =SUM(三家明細!I357) -> 121900 | I30: =SUM(三家明細!G543) -> 1 | J30: =三家明細!H543 -> 118000 | K30: =SUM(三家明細!I543) -> 118000 | L30: =IF(COUNT(D30,G30,J30)<3,"",MAX(D30,G30,J30)/MIN(D30,G30,J30)-1) -> 0.38559322 | M30: 尺寸近似，但材質、馬達及封板範圍待確認 | N30: dazhan-151、lidong-125、jiyi-123
A31: SD2快速捲門 | B31: 樘 | C31: =SUM(三家明細!G157) -> 1 | D31: =三家明細!H157 -> 173500 | E31: =SUM(三家明細!I157) -> 173500 | F31: =SUM(三家明細!G358) -> 1 | G31: =三家明細!H358 -> 135700 | H31: =SUM(三家明細!I358) -> 135700 | I31: =SUM(三家明細!G544) -> 1 | J31: =三家明細!H544 -> 128000 | K31: =SUM(三家明細!I544) -> 128000 | L31: =IF(COUNT(D31,G31,J31)<3,"",MAX(D31,G31,J31)/MIN(D31,G31,J31)-1) -> 0.35546875 | M31: 尺寸近似，但材質、馬達及封板範圍待確認 | N31: dazhan-152、lidong-126、jiyi-124
A32: SFD2防火捲門 | B32: 樘 | C32: =SUM(三家明細!G159) -> 2 | D32: =三家明細!H159 -> 285000 | E32: =SUM(三家明細!I159) -> 570000 | F32: =SUM(三家明細!G360) -> 2 | G32: =三家明細!H360 -> 242600 | H32: =SUM(三家明細!I360) -> 485200 | I32: =SUM(三家明細!G546) -> 2 | J32: =三家明細!H546 -> 265000 | K32: =SUM(三家明細!I546) -> 530000 | L32: =IF(COUNT(D32,G32,J32)<3,"",MAX(D32,G32,J32)/MIN(D32,G32,J32)-1) -> 0.17477329 | M32: 450×380；60A標示，相關控制及查驗待確認 | N32: dazhan-154、lidong-128、jiyi-126
A33: D1廁所門 | B33: 樘 | C33: =SUM(三家明細!G126) -> 4 | D33: =三家明細!H126 -> 10200 | E33: =SUM(三家明細!I126) -> 40800 | F33: =SUM(三家明細!G335) -> 4 | G33: =三家明細!H335 -> 16800 | H33: =SUM(三家明細!I335) -> 67200 | I33: =SUM(三家明細!G522) -> 4 | J33: =三家明細!H522 -> 4500 | K33: =SUM(三家明細!I522) -> 18000 | L33: =IF(COUNT(D33,G33,J33)<3,"",MAX(D33,G33,J33)/MIN(D33,G33,J33)-1) -> 2.7333333 | M33: 大展ABS；立東與基益SMC，材質不同 | N33: dazhan-121、lidong-103、jiyi-102
A34: D3a防火門 | B34: 樘 | C34: =SUM(三家明細!G129) -> 3 | D34: =三家明細!H129 -> 24300 | E34: =SUM(三家明細!I129) -> 72900 | F34: =SUM(三家明細!G338) -> 3 | G34: =三家明細!H338 -> 34600 | H34: =SUM(三家明細!I338) -> 103800 | I34: =SUM(三家明細!G525) -> 3 | J34: =三家明細!H525 -> 45000 | K34: =SUM(三家明細!I525) -> 135000 | L34: =IF(COUNT(D34,G34,J34)<3,"",MAX(D34,G34,J34)/MIN(D34,G34,J34)-1) -> 0.85185185 | M34: 大展60A；另兩家60B＋遮煙，規格不同 | N34: dazhan-124、lidong-106、jiyi-105
A35: W1鋁窗 | B35: 樘 | C35: =SUM(三家明細!G162) -> 23 | D35: =三家明細!H162 -> 9378 | E35: =SUM(三家明細!I162) -> 215694 | F35: =SUM(三家明細!G363) -> 23 | G35: =三家明細!H363 -> 12600 | H35: =SUM(三家明細!I363) -> 289800 | I35: =SUM(三家明細!G548) -> 27 | J35: =三家明細!H548 -> 14762 | K35: =SUM(三家明細!I548) -> 398574 | L35: =IF(COUNT(D35,G35,J35)<3,"",MAX(D35,G35,J35)/MIN(D35,G35,J35)-1) -> 0.57410962 | M35: 大展、基益玻璃另計，立東備註含玻璃，不能直比總成 | N35: dazhan-157、lidong-131、jiyi-128

Sheet 價差拆解
A2: 相對立東的價差拆解
A3: 數量效果＝(比較家數量－立東數量)×立東單價；單價效果＝比較家數量×單價差。含規格差異，並非純議價空間。
A5: 項目 | B5: 比較廠商 | C5: 複價差額 | D5: 數量效果 | E5: 單價效果 | F5: 乘算／精度差 | G5: 拆解核對 | H5: 比較限制
A6: 土方開挖 | B6: 大展營造 | C6: =IF(AND(ISNUMBER(單價與數量!C6),ISNUMBER(單價與數量!D6),ISNUMBER(單價與數量!F6),ISNUMBER(單價與數量!G6)),單價與數量!E6-單價與數量!H6,"") -> 108027 | D6: =IF(AND(ISNUMBER(單價與數量!C6),ISNUMBER(單價與數量!D6),ISNUMBER(單價與數量!F6),ISNUMBER(單價與數量!G6)),(單價與數量!C6-單價與數量!F6)*單價與數量!G6,"") -> -147835.8 | E6: =IF(AND(ISNUMBER(單價與數量!C6),ISNUMBER(單價與數量!D6),ISNUMBER(單價與數量!F6),ISNUMBER(單價與數量!G6)),單價與數量!C6*(單價與數量!D6-單價與數量!G6),"") -> 255862.8 | F6: =IF(C6="","",C6-D6-E6) -> -2.910383e-11 | G6: =IF(C6="","",C6-SUM(D6:F6)) -> 0 | H6: 深度、餘土及運棄範圍不同，需同版數量
A7: 土方開挖 | B7: 基益營造 | C7: =IF(AND(ISNUMBER(單價與數量!I6),ISNUMBER(單價與數量!J6),ISNUMBER(單價與數量!F6),ISNUMBER(單價與數量!G6)),單價與數量!K6-單價與數量!H6,"") -> 746595 | D7: =IF(AND(ISNUMBER(單價與數量!I6),ISNUMBER(單價與數量!J6),ISNUMBER(單價與數量!F6),ISNUMBER(單價與數量!G6)),(單價與數量!I6-單價與數量!F6)*單價與數量!G6,"") -> 679320 | E7: =IF(AND(ISNUMBER(單價與數量!I6),ISNUMBER(單價與數量!J6),ISNUMBER(單價與數量!F6),ISNUMBER(單價與數量!G6)),單價與數量!I6*(單價與數量!J6-單價與數量!G6),"") -> 67275 | F7: =IF(C7="","",C7-D7-E7) -> 0 | G7: =IF(C7="","",C7-SUM(D7:F7)) -> 0 | H7: 深度、餘土及運棄範圍不同，需同版數量
A8: 回填土方 | B8: 大展營造 | C8: =IF(AND(ISNUMBER(單價與數量!C7),ISNUMBER(單價與數量!D7),ISNUMBER(單價與數量!F7),ISNUMBER(單價與數量!G7)),單價與數量!E7-單價與數量!H7,"") -> -106734 | D8: =IF(AND(ISNUMBER(單價與數量!C7),ISNUMBER(單價與數量!D7),ISNUMBER(單價與數量!F7),ISNUMBER(單價與數量!G7)),(單價與數量!C7-單價與數量!F7)*單價與數量!G7,"") -> -135163.6 | E8: =IF(AND(ISNUMBER(單價與數量!C7),ISNUMBER(單價與數量!D7),ISNUMBER(單價與數量!F7),ISNUMBER(單價與數量!G7)),單價與數量!C7*(單價與數量!D7-單價與數量!G7),"") -> 28429.2 | F8: =IF(C8="","",C8-D8-E8) -> 0.4 | G8: =IF(C8="","",C8-SUM(D8:F8)) -> 0 | H8: 大展暫置基地內；另兩家夯實範圍需確認
A9: 回填土方 | B9: 基益營造 | C9: =IF(AND(ISNUMBER(單價與數量!I7),ISNUMBER(單價與數量!J7),ISNUMBER(單價與數量!F7),ISNUMBER(單價與數量!G7)),單價與數量!K7-單價與數量!H7,"") -> 307790 | D9: =IF(AND(ISNUMBER(單價與數量!I7),ISNUMBER(單價與數量!J7),ISNUMBER(單價與數量!F7),ISNUMBER(單價與數量!G7)),(單價與數量!I7-單價與數量!F7)*單價與數量!G7,"") -> 486540 | E9: =IF(AND(ISNUMBER(單價與數量!I7),ISNUMBER(單價與數量!J7),ISNUMBER(單價與數量!F7),ISNUMBER(單價與數量!G7)),單價與數量!I7*(單價與數量!J7-單價與數量!G7),"") -> -178750 | F9: =IF(C9="","",C9-D9-E9) -> 0 | G9: =IF(C9="","",C9-SUM(D9:F9)) -> 0 | H9: 大展暫置基地內；另兩家夯實範圍需確認
A10: 2000PSI混凝土 | B10: 大展營造 | C10: =IF(AND(ISNUMBER(單價與數量!C8),ISNUMBER(單價與數量!D8),ISNUMBER(單價與數量!F8),ISNUMBER(單價與數量!G8)),單價與數量!E8-單價與數量!H8,"") -> 574959 | D10: =IF(AND(ISNUMBER(單價與數量!C8),ISNUMBER(單價與數量!D8),ISNUMBER(單價與數量!F8),ISNUMBER(單價與數量!G8)),(單價與數量!C8-單價與數量!F8)*單價與數量!G8,"") -> 554914.5 | E10: =IF(AND(ISNUMBER(單價與數量!C8),ISNUMBER(單價與數量!D8),ISNUMBER(單價與數量!F8),ISNUMBER(單價與數量!G8)),單價與數量!C8*(單價與數量!D8-單價與數量!G8),"") -> 20044.5 | F10: =IF(C10="","",C10-D10-E10) -> -1.1641532e-10 | G10: =IF(C10="","",C10-SUM(D10:F10)) -> 0 | H10: 強度相近；品牌、配比及泵送條件待統一
A11: 2000PSI混凝土 | B11: 基益營造 | C11: =IF(AND(ISNUMBER(單價與數量!I8),ISNUMBER(單價與數量!J8),ISNUMBER(單價與數量!F8),ISNUMBER(單價與數量!G8)),單價與數量!K8-單價與數量!H8,"") -> 1008090 | D11: =IF(AND(ISNUMBER(單價與數量!I8),ISNUMBER(單價與數量!J8),ISNUMBER(單價與數量!F8),ISNUMBER(單價與數量!G8)),(單價與數量!I8-單價與數量!F8)*單價與數量!G8,"") -> 952840 | E11: =IF(AND(ISNUMBER(單價與數量!I8),ISNUMBER(單價與數量!J8),ISNUMBER(單價與數量!F8),ISNUMBER(單價與數量!G8)),單價與數量!I8*(單價與數量!J8-單價與數量!G8),"") -> 55250 | F11: =IF(C11="","",C11-D11-E11) -> 0 | G11: =IF(C11="","",C11-SUM(D11:F11)) -> 0 | H11: 強度相近；品牌、配比及泵送條件待統一
A12: 4000PSI混凝土 | B12: 大展營造 | C12: =IF(AND(ISNUMBER(單價與數量!C9),ISNUMBER(單價與數量!D9),ISNUMBER(單價與數量!F9),ISNUMBER(單價與數量!G9)),單價與數量!E9-單價與數量!H9,"") -> 658513 | D12: =IF(AND(ISNUMBER(單價與數量!C9),ISNUMBER(單價與數量!D9),ISNUMBER(單價與數量!F9),ISNUMBER(單價與數量!G9)),(單價與數量!C9-單價與數量!F9)*單價與數量!G9,"") -> 576098.7 | E12: =IF(AND(ISNUMBER(單價與數量!C9),ISNUMBER(單價與數量!D9),ISNUMBER(單價與數量!F9),ISNUMBER(單價與數量!G9)),單價與數量!C9*(單價與數量!D9-單價與數量!G9),"") -> 82424.1 | F12: =IF(C12="","",C12-D12-E12) -> -9.8 | G12: =IF(C12="","",C12-SUM(D12:F12)) -> 0 | H12: 強度相近；立東原複價有10元乘算差
A13: 4000PSI混凝土 | B13: 基益營造 | C13: =IF(AND(ISNUMBER(單價與數量!I9),ISNUMBER(單價與數量!J9),ISNUMBER(單價與數量!F9),ISNUMBER(單價與數量!G9)),單價與數量!K9-單價與數量!H9,"") -> -1332540 | D13: =IF(AND(ISNUMBER(單價與數量!I9),ISNUMBER(單價與數量!J9),ISNUMBER(單價與數量!F9),ISNUMBER(單價與數量!G9)),(單價與數量!I9-單價與數量!F9)*單價與數量!G9,"") -> -2481330 | E13: =IF(AND(ISNUMBER(單價與數量!I9),ISNUMBER(單價與數量!J9),ISNUMBER(單價與數量!F9),ISNUMBER(單價與數量!G9)),單價與數量!I9*(單價與數量!J9-單價與數量!G9),"") -> 1148800 | F13: =IF(C13="","",C13-D13-E13) -> -10 | G13: =IF(C13="","",C13-SUM(D13:F13)) -> 0 | H13: 強度相近；立東原複價有10元乘算差
A14: SD280鋼筋 | B14: 大展營造 | C14: =IF(AND(ISNUMBER(單價與數量!C10),ISNUMBER(單價與數量!D10),ISNUMBER(單價與數量!F10),ISNUMBER(單價與數量!G10)),單價與數量!E10-單價與數量!H10,"") -> 167608 | D14: =IF(AND(ISNUMBER(單價與數量!C10),ISNUMBER(單價與數量!D10),ISNUMBER(單價與數量!F10),ISNUMBER(單價與數量!G10)),(單價與數量!C10-單價與數量!F10)*單價與數量!G10,"") -> 206024 | E14: =IF(AND(ISNUMBER(單價與數量!C10),ISNUMBER(單價與數量!D10),ISNUMBER(單價與數量!F10),ISNUMBER(單價與數量!G10)),單價與數量!C10*(單價與數量!D10-單價與數量!G10),"") -> -38416 | F14: =IF(C14="","",C14-D14-E14) -> -2.910383e-11 | G14: =IF(C14="","",C14-SUM(D14:F14)) -> 0 | H14: 鋼筋號數範圍不一致；僅作數量與單價線索
A15: SD280鋼筋 | B15: 基益營造 | C15: =IF(AND(ISNUMBER(單價與數量!I10),ISNUMBER(單價與數量!J10),ISNUMBER(單價與數量!F10),ISNUMBER(單價與數量!G10)),單價與數量!K10-單價與數量!H10,"") -> 16992892 | D15: =IF(AND(ISNUMBER(單價與數量!I10),ISNUMBER(單價與數量!J10),ISNUMBER(單價與數量!F10),ISNUMBER(單價與數量!G10)),(單價與數量!I10-單價與數量!F10)*單價與數量!G10,"") -> 15826492 | E15: =IF(AND(ISNUMBER(單價與數量!I10),ISNUMBER(單價與數量!J10),ISNUMBER(單價與數量!F10),ISNUMBER(單價與數量!G10)),單價與數量!I10*(單價與數量!J10-單價與數量!G10),"") -> 1166400 | F15: =IF(C15="","",C15-D15-E15) -> 0 | G15: =IF(C15="","",C15-SUM(D15:F15)) -> 0 | H15: 鋼筋號數範圍不一致；僅作數量與單價線索
A16: SD420鋼筋 | B16: 大展營造 | C16: =IF(AND(ISNUMBER(單價與數量!C11),ISNUMBER(單價與數量!D11),ISNUMBER(單價與數量!F11),ISNUMBER(單價與數量!G11)),單價與數量!E11-單價與數量!H11,"") -> 1129565 | D16: =IF(AND(ISNUMBER(單價與數量!C11),ISNUMBER(單價與數量!D11),ISNUMBER(單價與數量!F11),ISNUMBER(單價與數量!G11)),(單價與數量!C11-單價與數量!F11)*單價與數量!G11,"") -> 1255600 | E16: =IF(AND(ISNUMBER(單價與數量!C11),ISNUMBER(單價與數量!D11),ISNUMBER(單價與數量!F11),ISNUMBER(單價與數量!G11)),單價與數量!C11*(單價與數量!D11-單價與數量!G11),"") -> -126035 | F16: =IF(C16="","",C16-D16-E16) -> 0 | G16: =IF(C16="","",C16-SUM(D16:F16)) -> 0 | H16: 大展#4以上；基益#6–#11，號數範圍不一致
A17: SD420鋼筋 | B17: 基益營造 | C17: =IF(AND(ISNUMBER(單價與數量!I11),ISNUMBER(單價與數量!J11),ISNUMBER(單價與數量!F11),ISNUMBER(單價與數量!G11)),單價與數量!K11-單價與數量!H11,"") -> 4615156 | D17: =IF(AND(ISNUMBER(單價與數量!I11),ISNUMBER(單價與數量!J11),ISNUMBER(單價與數量!F11),ISNUMBER(單價與數量!G11)),(單價與數量!I11-單價與數量!F11)*單價與數量!G11,"") -> 3677156 | E17: =IF(AND(ISNUMBER(單價與數量!I11),ISNUMBER(單價與數量!J11),ISNUMBER(單價與數量!F11),ISNUMBER(單價與數量!G11)),單價與數量!I11*(單價與數量!J11-單價與數量!G11),"") -> 938000 | F17: =IF(C17="","",C17-D17-E17) -> 0 | G17: =IF(C17="","",C17-SUM(D17:F17)) -> 0 | H17: 大展#4以上；基益#6–#11，號數範圍不一致
A18: 普通／系統模板 | B18: 大展營造 | C18: =IF(AND(ISNUMBER(單價與數量!C12),ISNUMBER(單價與數量!D12),ISNUMBER(單價與數量!F12),ISNUMBER(單價與數量!G12)),單價與數量!E12-單價與數量!H12,"") -> -1362022 | D18: =IF(AND(ISNUMBER(單價與數量!C12),ISNUMBER(單價與數量!D12),ISNUMBER(單價與數量!F12),ISNUMBER(單價與數量!G12)),(單價與數量!C12-單價與數量!F12)*單價與數量!G12,"") -> 141979.5 | E18: =IF(AND(ISNUMBER(單價與數量!C12),ISNUMBER(單價與數量!D12),ISNUMBER(單價與數量!F12),ISNUMBER(單價與數量!G12)),單價與數量!C12*(單價與數量!D12-單價與數量!G12),"") -> -1504002 | F18: =IF(C18="","",C18-D18-E18) -> 0.5 | G18: =IF(C18="","",C18-SUM(D18:F18)) -> 0 | H18: 基益為兩種模板加權單價；面積與模板型式不同
A19: 普通／系統模板 | B19: 基益營造 | C19: =IF(AND(ISNUMBER(單價與數量!I12),ISNUMBER(單價與數量!J12),ISNUMBER(單價與數量!F12),ISNUMBER(單價與數量!G12)),單價與數量!K12-單價與數量!H12,"") -> 2321210 | D19: =IF(AND(ISNUMBER(單價與數量!I12),ISNUMBER(單價與數量!J12),ISNUMBER(單價與數量!F12),ISNUMBER(單價與數量!G12)),(單價與數量!I12-單價與數量!F12)*單價與數量!G12,"") -> 348660 | E19: =IF(AND(ISNUMBER(單價與數量!I12),ISNUMBER(單價與數量!J12),ISNUMBER(單價與數量!F12),ISNUMBER(單價與數量!G12)),單價與數量!I12*(單價與數量!J12-單價與數量!G12),"") -> 1972550 | F19: =IF(C19="","",C19-D19-E19) -> -6.9849193e-10 | G19: =IF(C19="","",C19-SUM(D19:F19)) -> 0 | H19: 基益為兩種模板加權單價；面積與模板型式不同
A20: EPOXY地坪 | B20: 大展營造 | C20: =IF(AND(ISNUMBER(單價與數量!C13),ISNUMBER(單價與數量!D13),ISNUMBER(單價與數量!F13),ISNUMBER(單價與數量!G13)),單價與數量!E13-單價與數量!H13,"") -> -1461628 | D20: =IF(AND(ISNUMBER(單價與數量!C13),ISNUMBER(單價與數量!D13),ISNUMBER(單價與數量!F13),ISNUMBER(單價與數量!G13)),(單價與數量!C13-單價與數量!F13)*單價與數量!G13,"") -> 89056.8 | E20: =IF(AND(ISNUMBER(單價與數量!C13),ISNUMBER(單價與數量!D13),ISNUMBER(單價與數量!F13),ISNUMBER(單價與數量!G13)),單價與數量!C13*(單價與數量!D13-單價與數量!G13),"") -> -1550684.6 | F20: =IF(C20="","",C20-D20-E20) -> -0.2 | G20: =IF(C20="","",C20-SUM(D20:F20)) -> 0 | H20: 大展3mm、立東5mm且含粉光；基益厚度未列
A21: EPOXY地坪 | B21: 基益營造 | C21: =IF(AND(ISNUMBER(單價與數量!I13),ISNUMBER(單價與數量!J13),ISNUMBER(單價與數量!F13),ISNUMBER(單價與數量!G13)),單價與數量!K13-單價與數量!H13,"") -> -28960 | D21: =IF(AND(ISNUMBER(單價與數量!I13),ISNUMBER(單價與數量!J13),ISNUMBER(單價與數量!F13),ISNUMBER(單價與數量!G13)),(單價與數量!I13-單價與數量!F13)*單價與數量!G13,"") -> 88040 | E21: =IF(AND(ISNUMBER(單價與數量!I13),ISNUMBER(單價與數量!J13),ISNUMBER(單價與數量!F13),ISNUMBER(單價與數量!G13)),單價與數量!I13*(單價與數量!J13-單價與數量!G13),"") -> -117000 | F21: =IF(C21="","",C21-D21-E21) -> 0 | G21: =IF(C21="","",C21-SUM(D21:F21)) -> 0 | H21: 大展3mm、立東5mm且含粉光；基益厚度未列
A22: 明架礦纖天花 | B22: 大展營造 | C22: =IF(AND(ISNUMBER(單價與數量!C14),ISNUMBER(單價與數量!D14),ISNUMBER(單價與數量!F14),ISNUMBER(單價與數量!G14)),單價與數量!E14-單價與數量!H14,"") -> -102801 | D22: =IF(AND(ISNUMBER(單價與數量!C14),ISNUMBER(單價與數量!D14),ISNUMBER(單價與數量!F14),ISNUMBER(單價與數量!G14)),(單價與數量!C14-單價與數量!F14)*單價與數量!G14,"") -> 12209.4 | E22: =IF(AND(ISNUMBER(單價與數量!C14),ISNUMBER(單價與數量!D14),ISNUMBER(單價與數量!F14),ISNUMBER(單價與數量!G14)),單價與數量!C14*(單價與數量!D14-單價與數量!G14),"") -> -115010.4 | F22: =IF(C22="","",C22-D22-E22) -> 1.4551915e-11 | G22: =IF(C22="","",C22-SUM(D22:F22)) -> 0 | H22: 60×60；品牌、骨架及收邊待統一
A23: 明架礦纖天花 | B23: 基益營造 | C23: =IF(AND(ISNUMBER(單價與數量!I14),ISNUMBER(單價與數量!J14),ISNUMBER(單價與數量!F14),ISNUMBER(單價與數量!G14)),單價與數量!K14-單價與數量!H14,"") -> 610708 | D23: =IF(AND(ISNUMBER(單價與數量!I14),ISNUMBER(單價與數量!J14),ISNUMBER(單價與數量!F14),ISNUMBER(單價與數量!G14)),(單價與數量!I14-單價與數量!F14)*單價與數量!G14,"") -> 152788.5 | E23: =IF(AND(ISNUMBER(單價與數量!I14),ISNUMBER(單價與數量!J14),ISNUMBER(單價與數量!F14),ISNUMBER(單價與數量!G14)),單價與數量!I14*(單價與數量!J14-單價與數量!G14),"") -> 457919 | F23: =IF(C23="","",C23-D23-E23) -> 0.5 | G23: =IF(C23="","",C23-SUM(D23:F23)) -> 0 | H23: 60×60；品牌、骨架及收邊待統一
A24: 暗架矽酸鈣天花 | B24: 大展營造 | C24: =IF(AND(ISNUMBER(單價與數量!C15),ISNUMBER(單價與數量!D15),ISNUMBER(單價與數量!F15),ISNUMBER(單價與數量!G15)),單價與數量!E15-單價與數量!H15,"") -> -33750 | D24: =IF(AND(ISNUMBER(單價與數量!C15),ISNUMBER(單價與數量!D15),ISNUMBER(單價與數量!F15),ISNUMBER(單價與數量!G15)),(單價與數量!C15-單價與數量!F15)*單價與數量!G15,"") -> -65926.2 | E24: =IF(AND(ISNUMBER(單價與數量!C15),ISNUMBER(單價與數量!D15),ISNUMBER(單價與數量!F15),ISNUMBER(單價與數量!G15)),單價與數量!C15*(單價與數量!D15-單價與數量!G15),"") -> 32175.9 | F24: =IF(C24="","",C24-D24-E24) -> 0.3 | G24: =IF(C24="","",C24-SUM(D24:F24)) -> 0 | H24: 油漆、板厚與收邊內容不同
A25: 暗架矽酸鈣天花 | B25: 基益營造 | C25: =IF(AND(ISNUMBER(單價與數量!I15),ISNUMBER(單價與數量!J15),ISNUMBER(單價與數量!F15),ISNUMBER(單價與數量!G15)),單價與數量!K15-單價與數量!H15,"") -> 227635 | D25: =IF(AND(ISNUMBER(單價與數量!I15),ISNUMBER(單價與數量!J15),ISNUMBER(單價與數量!F15),ISNUMBER(單價與數量!G15)),(單價與數量!I15-單價與數量!F15)*單價與數量!G15,"") -> -61913.4 | E25: =IF(AND(ISNUMBER(單價與數量!I15),ISNUMBER(單價與數量!J15),ISNUMBER(單價與數量!F15),ISNUMBER(單價與數量!G15)),單價與數量!I15*(單價與數量!J15-單價與數量!G15),"") -> 289548.4 | F25: =IF(C25="","",C25-D25-E25) -> 0 | G25: =IF(C25="","",C25-SUM(D25:F25)) -> -2.910383e-11 | H25: 油漆、板厚與收邊內容不同
A26: 一般輕隔間 | B26: 大展營造 | C26: =IF(AND(ISNUMBER(單價與數量!C16),ISNUMBER(單價與數量!D16),ISNUMBER(單價與數量!F16),ISNUMBER(單價與數量!G16)),單價與數量!E16-單價與數量!H16,"") -> -263662 | D26: =IF(AND(ISNUMBER(單價與數量!C16),ISNUMBER(單價與數量!D16),ISNUMBER(單價與數量!F16),ISNUMBER(單價與數量!G16)),(單價與數量!C16-單價與數量!F16)*單價與數量!G16,"") -> -552457.5 | E26: =IF(AND(ISNUMBER(單價與數量!C16),ISNUMBER(單價與數量!D16),ISNUMBER(單價與數量!F16),ISNUMBER(單價與數量!G16)),單價與數量!C16*(單價與數量!D16-單價與數量!G16),"") -> 288795 | F26: =IF(C26="","",C26-D26-E26) -> 0.5 | G26: =IF(C26="","",C26-SUM(D26:F26)) -> 0 | H26: 大展一般型；立東不含岩棉；基益10cm牆厚
A27: 一般輕隔間 | B27: 基益營造 | C27: =IF(AND(ISNUMBER(單價與數量!I16),ISNUMBER(單價與數量!J16),ISNUMBER(單價與數量!F16),ISNUMBER(單價與數量!G16)),單價與數量!K16-單價與數量!H16,"") -> 5901250 | D27: =IF(AND(ISNUMBER(單價與數量!I16),ISNUMBER(單價與數量!J16),ISNUMBER(單價與數量!F16),ISNUMBER(單價與數量!G16)),(單價與數量!I16-單價與數量!F16)*單價與數量!G16,"") -> 1826888 | E27: =IF(AND(ISNUMBER(單價與數量!I16),ISNUMBER(單價與數量!J16),ISNUMBER(單價與數量!F16),ISNUMBER(單價與數量!G16)),單價與數量!I16*(單價與數量!J16-單價與數量!G16),"") -> 4074362 | F27: =IF(C27="","",C27-D27-E27) -> 4.6566129e-10 | G27: =IF(C27="","",C27-SUM(D27:F27)) -> 0 | H27: 大展一般型；立東不含岩棉；基益10cm牆厚
A28: RC內牆粉光油漆 | B28: 大展營造 | C28: =IF(AND(ISNUMBER(單價與數量!C17),ISNUMBER(單價與數量!D17),ISNUMBER(單價與數量!F17),ISNUMBER(單價與數量!G17)),單價與數量!E17-單價與數量!H17,"") -> -321832 | D28: =IF(AND(ISNUMBER(單價與數量!C17),ISNUMBER(單價與數量!D17),ISNUMBER(單價與數量!F17),ISNUMBER(單價與數量!G17)),(單價與數量!C17-單價與數量!F17)*單價與數量!G17,"") -> -549125.5 | E28: =IF(AND(ISNUMBER(單價與數量!C17),ISNUMBER(單價與數量!D17),ISNUMBER(單價與數量!F17),ISNUMBER(單價與數量!G17)),單價與數量!C17*(單價與數量!D17-單價與數量!G17),"") -> 227293.2 | F28: =IF(C28="","",C28-D28-E28) -> 0.3 | G28: =IF(C28="","",C28-SUM(D28:F28)) -> 0 | H28: 施作面積、塗料與分項範圍不同
A29: RC內牆粉光油漆 | B29: 基益營造 | C29: =IF(AND(ISNUMBER(單價與數量!I17),ISNUMBER(單價與數量!J17),ISNUMBER(單價與數量!F17),ISNUMBER(單價與數量!G17)),單價與數量!K17-單價與數量!H17,"") -> 7074821 | D29: =IF(AND(ISNUMBER(單價與數量!I17),ISNUMBER(單價與數量!J17),ISNUMBER(單價與數量!F17),ISNUMBER(單價與數量!G17)),(單價與數量!I17-單價與數量!F17)*單價與數量!G17,"") -> 2359503.3 | E29: =IF(AND(ISNUMBER(單價與數量!I17),ISNUMBER(單價與數量!J17),ISNUMBER(單價與數量!F17),ISNUMBER(單價與數量!G17)),單價與數量!I17*(單價與數量!J17-單價與數量!G17),"") -> 4715317.2 | F29: =IF(C29="","",C29-D29-E29) -> 0.5 | G29: =IF(C29="","",C29-SUM(D29:F29)) -> 0 | H29: 施作面積、塗料與分項範圍不同
A30: 輕隔間批土油漆 | B30: 大展營造 | C30: =IF(AND(ISNUMBER(單價與數量!C18),ISNUMBER(單價與數量!D18),ISNUMBER(單價與數量!F18),ISNUMBER(單價與數量!G18)),單價與數量!E18-單價與數量!H18,"") -> 275887 | D30: =IF(AND(ISNUMBER(單價與數量!C18),ISNUMBER(單價與數量!D18),ISNUMBER(單價與數量!F18),ISNUMBER(單價與數量!G18)),(單價與數量!C18-單價與數量!F18)*單價與數量!G18,"") -> 7809.2 | E30: =IF(AND(ISNUMBER(單價與數量!C18),ISNUMBER(單價與數量!D18),ISNUMBER(單價與數量!F18),ISNUMBER(單價與數量!G18)),單價與數量!C18*(單價與數量!D18-單價與數量!G18),"") -> 268078 | F30: =IF(C30="","",C30-D30-E30) -> -0.2 | G30: =IF(C30="","",C30-SUM(D30:F30)) -> 0 | H30: 品牌與塗裝道數待核對
A31: 輕隔間批土油漆 | B31: 基益營造 | C31: =IF(AND(ISNUMBER(單價與數量!I18),ISNUMBER(單價與數量!J18),ISNUMBER(單價與數量!F18),ISNUMBER(單價與數量!G18)),單價與數量!K18-單價與數量!H18,"") -> 502355 | D31: =IF(AND(ISNUMBER(單價與數量!I18),ISNUMBER(單價與數量!J18),ISNUMBER(單價與數量!F18),ISNUMBER(單價與數量!G18)),(單價與數量!I18-單價與數量!F18)*單價與數量!G18,"") -> -19558 | E31: =IF(AND(ISNUMBER(單價與數量!I18),ISNUMBER(單價與數量!J18),ISNUMBER(單價與數量!F18),ISNUMBER(單價與數量!G18)),單價與數量!I18*(單價與數量!J18-單價與數量!G18),"") -> 521913 | F31: =IF(C31="","",C31-D31-E31) -> -5.8207661e-11 | G31: =IF(C31="","",C31-SUM(D31:F31)) -> 0 | H31: 品牌與塗裝道數待核對
A32: 外牆二丁掛磚 | B32: 大展營造 | C32: =IF(AND(ISNUMBER(單價與數量!C19),ISNUMBER(單價與數量!D19),ISNUMBER(單價與數量!F19),ISNUMBER(單價與數量!G19)),單價與數量!E19-單價與數量!H19,"") -> -105824 | D32: =IF(AND(ISNUMBER(單價與數量!C19),ISNUMBER(單價與數量!D19),ISNUMBER(單價與數量!F19),ISNUMBER(單價與數量!G19)),(單價與數量!C19-單價與數量!F19)*單價與數量!G19,"") -> -604964.4 | E32: =IF(AND(ISNUMBER(單價與數量!C19),ISNUMBER(單價與數量!D19),ISNUMBER(單價與數量!F19),ISNUMBER(單價與數量!G19)),單價與數量!C19*(單價與數量!D19-單價與數量!G19),"") -> 499143.62 | F32: =IF(C32="","",C32-D32-E32) -> -3.22 | G32: =IF(C32="","",C32-SUM(D32:F32)) -> 0 | H32: 磚款、基層及計量面積不同
A33: 外牆二丁掛磚 | B33: 基益營造 | C33: =IF(AND(ISNUMBER(單價與數量!I19),ISNUMBER(單價與數量!J19),ISNUMBER(單價與數量!F19),ISNUMBER(單價與數量!G19)),單價與數量!K19-單價與數量!H19,"") -> -721638 | D33: =IF(AND(ISNUMBER(單價與數量!I19),ISNUMBER(單價與數量!J19),ISNUMBER(單價與數量!F19),ISNUMBER(單價與數量!G19)),(單價與數量!I19-單價與數量!F19)*單價與數量!G19,"") -> -1869210 | E33: =IF(AND(ISNUMBER(單價與數量!I19),ISNUMBER(單價與數量!J19),ISNUMBER(單價與數量!F19),ISNUMBER(單價與數量!G19)),單價與數量!I19*(單價與數量!J19-單價與數量!G19),"") -> 1147575 | F33: =IF(C33="","",C33-D33-E33) -> -3 | G33: =IF(C33="","",C33-SUM(D33:F33)) -> 0 | H33: 磚款、基層及計量面積不同
A34: 外牆金屬包板 | B34: 大展營造 | C34: =IF(AND(ISNUMBER(單價與數量!C20),ISNUMBER(單價與數量!D20),ISNUMBER(單價與數量!F20),ISNUMBER(單價與數量!G20)),單價與數量!E20-單價與數量!H20,"") -> 181480 | D34: =IF(AND(ISNUMBER(單價與數量!C20),ISNUMBER(單價與數量!D20),ISNUMBER(單價與數量!F20),ISNUMBER(單價與數量!G20)),(單價與數量!C20-單價與數量!F20)*單價與數量!G20,"") -> -26415.2 | E34: =IF(AND(ISNUMBER(單價與數量!C20),ISNUMBER(單價與數量!D20),ISNUMBER(單價與數量!F20),ISNUMBER(單價與數量!G20)),單價與數量!C20*(單價與數量!D20-單價與數量!G20),"") -> 207895.2 | F34: =IF(C34="","",C34-D34-E34) -> 0 | G34: =IF(C34="","",C34-SUM(D34:F34)) -> 0 | H34: 大展2.5t鋁板含骨架；另兩家厚度待確認
A35: 外牆金屬包板 | B35: 基益營造 | C35: =IF(AND(ISNUMBER(單價與數量!I20),ISNUMBER(單價與數量!J20),ISNUMBER(單價與數量!F20),ISNUMBER(單價與數量!G20)),單價與數量!K20-單價與數量!H20,"") -> 3456460 | D35: =IF(AND(ISNUMBER(單價與數量!I20),ISNUMBER(單價與數量!J20),ISNUMBER(單價與數量!F20),ISNUMBER(單價與數量!G20)),(單價與數量!I20-單價與數量!F20)*單價與數量!G20,"") -> 4325860 | E35: =IF(AND(ISNUMBER(單價與數量!I20),ISNUMBER(單價與數量!J20),ISNUMBER(單價與數量!F20),ISNUMBER(單價與數量!G20)),單價與數量!I20*(單價與數量!J20-單價與數量!G20),"") -> -869400 | F35: =IF(C35="","",C35-D35-E35) -> 0 | G35: =IF(C35="","",C35-SUM(D35:F35)) -> 0 | H35: 大展2.5t鋁板含骨架；另兩家厚度待確認
A36: 仿清水模塗料 | B36: 大展營造 | C36: =IF(AND(ISNUMBER(單價與數量!C21),ISNUMBER(單價與數量!D21),ISNUMBER(單價與數量!F21),ISNUMBER(單價與數量!G21)),單價與數量!E21-單價與數量!H21,"") -> 65629 | D36: =IF(AND(ISNUMBER(單價與數量!C21),ISNUMBER(單價與數量!D21),ISNUMBER(單價與數量!F21),ISNUMBER(單價與數量!G21)),(單價與數量!C21-單價與數量!F21)*單價與數量!G21,"") -> 82976.4 | E36: =IF(AND(ISNUMBER(單價與數量!C21),ISNUMBER(單價與數量!D21),ISNUMBER(單價與數量!F21),ISNUMBER(單價與數量!G21)),單價與數量!C21*(單價與數量!D21-單價與數量!G21),"") -> -17347.2 | F36: =IF(C36="","",C36-D36-E36) -> -0.2 | G36: =IF(C36="","",C36-SUM(D36:F36)) -> 0 | H36: 大展鈴鹿；立東國產；基益品牌未列
A37: 仿清水模塗料 | B37: 基益營造 | C37: =IF(AND(ISNUMBER(單價與數量!I21),ISNUMBER(單價與數量!J21),ISNUMBER(單價與數量!F21),ISNUMBER(單價與數量!G21)),單價與數量!K21-單價與數量!H21,"") -> 63232 | D37: =IF(AND(ISNUMBER(單價與數量!I21),ISNUMBER(單價與數量!J21),ISNUMBER(單價與數量!F21),ISNUMBER(單價與數量!G21)),(單價與數量!I21-單價與數量!F21)*單價與數量!G21,"") -> 29195.4 | E37: =IF(AND(ISNUMBER(單價與數量!I21),ISNUMBER(單價與數量!J21),ISNUMBER(單價與數量!F21),ISNUMBER(單價與數量!G21)),單價與數量!I21*(單價與數量!J21-單價與數量!G21),"") -> 34036.6 | F37: =IF(C37="","",C37-D37-E37) -> 1.4551915e-11 | G37: =IF(C37="","",C37-SUM(D37:F37)) -> 0 | H37: 大展鈴鹿；立東國產；基益品牌未列
A38: 淺色外牆塗料 | B38: 大展營造 | C38: =IF(AND(ISNUMBER(單價與數量!C22),ISNUMBER(單價與數量!D22),ISNUMBER(單價與數量!F22),ISNUMBER(單價與數量!G22)),單價與數量!E22-單價與數量!H22,"") -> -175801 | D38: =IF(AND(ISNUMBER(單價與數量!C22),ISNUMBER(單價與數量!D22),ISNUMBER(單價與數量!F22),ISNUMBER(單價與數量!G22)),(單價與數量!C22-單價與數量!F22)*單價與數量!G22,"") -> -109746.8 | E38: =IF(AND(ISNUMBER(單價與數量!C22),ISNUMBER(單價與數量!D22),ISNUMBER(單價與數量!F22),ISNUMBER(單價與數量!G22)),單價與數量!C22*(單價與數量!D22-單價與數量!G22),"") -> -66054 | F38: =IF(C38="","",C38-D38-E38) -> -0.2 | G38: =IF(C38="","",C38-SUM(D38:F38)) -> 0 | H38: 品牌與工法不同
A39: 淺色外牆塗料 | B39: 基益營造 | C39: =IF(AND(ISNUMBER(單價與數量!I22),ISNUMBER(單價與數量!J22),ISNUMBER(單價與數量!F22),ISNUMBER(單價與數量!G22)),單價與數量!K22-單價與數量!H22,"") -> -533853 | D39: =IF(AND(ISNUMBER(單價與數量!I22),ISNUMBER(單價與數量!J22),ISNUMBER(單價與數量!F22),ISNUMBER(單價與數量!G22)),(單價與數量!I22-單價與數量!F22)*單價與數量!G22,"") -> -624273.8 | E39: =IF(AND(ISNUMBER(單價與數量!I22),ISNUMBER(單價與數量!J22),ISNUMBER(單價與數量!F22),ISNUMBER(單價與數量!G22)),單價與數量!I22*(單價與數量!J22-單價與數量!G22),"") -> 90420.3 | F39: =IF(C39="","",C39-D39-E39) -> 0.5 | G39: =IF(C39="","",C39-SUM(D39:F39)) -> 0 | H39: 品牌與工法不同
A40: 屋頂平台防水 | B40: 大展營造 | C40: =IF(AND(ISNUMBER(單價與數量!C23),ISNUMBER(單價與數量!D23),ISNUMBER(單價與數量!F23),ISNUMBER(單價與數量!G23)),單價與數量!E23-單價與數量!H23,"") -> 1372496 | D40: =IF(AND(ISNUMBER(單價與數量!C23),ISNUMBER(單價與數量!D23),ISNUMBER(單價與數量!F23),ISNUMBER(單價與數量!G23)),(單價與數量!C23-單價與數量!F23)*單價與數量!G23,"") -> -178631.2 | E40: =IF(AND(ISNUMBER(單價與數量!C23),ISNUMBER(單價與數量!D23),ISNUMBER(單價與數量!F23),ISNUMBER(單價與數量!G23)),單價與數量!C23*(單價與數量!D23-單價與數量!G23),"") -> 1551129.2 | F40: =IF(C40="","",C40-D40-E40) -> -2 | G40: =IF(C40="","",C40-SUM(D40:F40)) -> 0 | H40: 聚脲／彈泥／未詳工法，不宜作同規格排名
A41: 屋頂平台防水 | B41: 基益營造 | C41: =IF(AND(ISNUMBER(單價與數量!I23),ISNUMBER(單價與數量!J23),ISNUMBER(單價與數量!F23),ISNUMBER(單價與數量!G23)),單價與數量!K23-單價與數量!H23,"") -> -569377 | D41: =IF(AND(ISNUMBER(單價與數量!I23),ISNUMBER(單價與數量!J23),ISNUMBER(單價與數量!F23),ISNUMBER(單價與數量!G23)),(單價與數量!I23-單價與數量!F23)*單價與數量!G23,"") -> -379931.2 | E41: =IF(AND(ISNUMBER(單價與數量!I23),ISNUMBER(單價與數量!J23),ISNUMBER(單價與數量!F23),ISNUMBER(單價與數量!G23)),單價與數量!I23*(單價與數量!J23-單價與數量!G23),"") -> -189443.8 | F41: =IF(C41="","",C41-D41-E41) -> -2 | G41: =IF(C41="","",C41-SUM(D41:F41)) -> 0 | H41: 聚脲／彈泥／未詳工法，不宜作同規格排名
A42: 客用無障礙電梯 | B42: 大展營造 | C42: =IF(AND(ISNUMBER(單價與數量!C24),ISNUMBER(單價與數量!D24),ISNUMBER(單價與數量!F24),ISNUMBER(單價與數量!G24)),單價與數量!E24-單價與數量!H24,"") | D42: =IF(AND(ISNUMBER(單價與數量!C24),ISNUMBER(單價與數量!D24),ISNUMBER(單價與數量!F24),ISNUMBER(單價與數量!G24)),(單價與數量!C24-單價與數量!F24)*單價與數量!G24,"") | E42: =IF(AND(ISNUMBER(單價與數量!C24),ISNUMBER(單價與數量!D24),ISNUMBER(單價與數量!F24),ISNUMBER(單價與數量!G24)),單價與數量!C24*(單價與數量!D24-單價與數量!G24),"") | F42: =IF(C42="","",C42-D42-E42) | G42: =IF(C42="","",C42-SUM(D42:F42)) | H42: 大展不含；立東立穩/國峰，基益小金井
...

Sheet 範圍品牌條款
A2: 範圍、品牌與報價條件
A5: 比較主題 | B5: 大展營造 | C5: 立東營造 | D5: 基益營造 | E5: 應確認事項 | F5: PDF依據
A6: 電梯設備 | B6: 不含，業主自理；施工時需無償借用 | C6: 客梯1,243,800＋貨梯2,448,900；立穩、國峰或同等 | D6: 客梯938,000＋貨梯2,580,000；小金井 | E6: 大展須另補；另兩家停靠、載重及規格仍需統一 | F6: 大展p1；立東p7；基益p7
A7: 機電／衛浴／安全設備 | B7: 明列不含設備及承裝 | C7: 機電業主自行發包 | D7: 本份未列獨立機電工程，是否另包待確認 | E7: 三家總額均不能當作完整建廠預算 | F7: 大展p1；立東p1；基益p1及全表
A8: 空污費 | B8: 不含，業主自理 | C8: 業主支付環保署，無金額 | D8: 總表另列65,000，列於營業稅之後 | E8: 含價範圍不同；不替未列金額估零 | F8: 三家p1
A9: 臨時水電 | B9: 首頁不含申請外管線路費，但A003列717,000、A004列360,000 | C9: 首頁不含臨時水電；明細列102,000使用費，代辦供應設備甲方提供 | D9: 申請配管拉線註威向水電；使用費業主自理 | E9: 大展、立東條款與明細範圍需書面釐清 | F9: 大展p1、p4；立東p1、p2；基益p2
A10: 外水／外電／外瓦斯／外審 | B10: 臨時水電外管費明列不含，其餘未明 | C10: 全部明列不含 | D10: 未明列 | E10: 要求各家列清規費與接管分界 | F10: 大展p1；立東p1；基益全表
A11: 混凝土品牌 | B11: 2000PSI台鋼；4000PSI亞泥 | C11: 亞東、巨力等同等品牌 | D11: 未列品牌 | E11: 相同強度仍需確認配比、泵送及查驗要求 | F11: 大展p7；立東p1–3；基益p2
A12: 鋼材與樓承板 | B12: SN490B；主體DECK 1.2mm | C12: SN490YB／SN400B；Z275 DECK 1.5mm | D12: SN490YB；1.5與1.2mm並列，含鋅量120g | E12: 材級、板厚、鍍鋅量不同，不能只比每公斤或每坪單價 | F12: 大展p6；立東p3–4；基益p3
A13: 鋁門窗與玻璃 | B13: 信元；多數5灰＋5清雙強膠合，玻璃另列 | C13: 大同、力霸等同等；多數5清＋5灰強化，部分含隱藏紗窗與三點連動 | D13: 國田；8mm強化玻璃另列 | E13: 合併玻璃、五金、紗窗、填縫後再比價；不同門型不可直接比 | F13: 大展p2、p13–17；立東p1、p6–7；基益p6–7
A14: 輕隔間 | B14: 國浦；防火與管道間含岩棉，另有一般隔間 | C14: 9mm矽酸鈣板；不含岩棉 | D14: T=10CM；未列品牌或岩棉 | E14: 分清總牆厚、板厚、骨架、岩棉與防火時效 | F14: 大展p8；立東p1、p5；基益p4
A15: EPOXY地坪 | B15: 慶泰3mm流展平塗，整體粉光另列E001 | C15: 5mm EPOXY，含地坪整體粉光 | D15: 未列厚度，地坪EPOXY | E15: 厚度及粉光範圍不同；大展710與立東1,240不可直接判定價差效益 | F15: 大展p8；立東p4；基益p4
A16: 屋頂防水 | B16: 3mm聚脲1,800元/M2 | C16: 彈泥五道、全面貼纖維網880元/M2 | D16: 750元/M2，工法未詳列 | E16: 工法不同；統一保固、試水、收頭與施工範圍 | F16: 大展p3、p10；立東p4；基益p4
... A23: 版本與承攬主體 | B23: PDF20頁，頁首標示共41頁 | C23: 使用者檔名立東；抬頭立東建設／營寶營造 | D23: 日期2026/4/1，較其他報價早約半年 | E23: 取得同版圖說、完整附件、法人抬頭後再決標 | F23: 三家首頁及文件頁數

Sheet 待確認事項
A2: 議價與核對清單
A5: 廠商 | B5: 事項 | C5: 優先程度 | D5: 具體確認內容 | E5: PDF依據 | F5: 回覆／處理紀錄
A6: 三家 | B6: 同版圖說與範圍 | C6: 高 | D6: 先取得相同建築、結構、門窗及機台基礎圖版本，再請三家重估同一工程數量。 | E6: 三家全表
A7: 大展營造 | B7: 電梯未含 | C7: 高 | D7: 補客梯、貨梯與周邊防火設備承裝報價，才有同範圍比較基礎。 | E7: p1
A8: 大展營造 | B8: 文件頁數 | C8: 中 | D8: 提供PDF20頁，頁首印共41頁，請確認是否尚有附件。 | E8: p1–20
A9: 立東營造 | B9: 法人抬頭 | C9: 高 | D9: 確認實際簽約、開票與施工承攬主體；PDF抬頭與檔名不完全相同。 | E9: p1
A10: 基益營造 | B10: 舊版與大量差異 | C10: 高 | D10: 2026/4/1版本；鋼筋共983噸，另兩家約348.11／297.83噸，需先核圖量。 | E10: p2；大展p7；立東p2
A11: 大展營造／立東營造 | B11: 臨時水電條款 | C11: 高 | D11: 總備註不含臨時水電或申請外管費，但明細有價；請書面界定。 | E11: 大展p1、4；立東p1、2
A12: 基益營造 | B12: 防水乘算差異 | C12: 中 | D12: 窗框1,348×300=404,400，原337,000；接縫1,341×300=402,300，原335,250。合計差134,450元，原值保留。 | E12: p4
A13: 基益營造 | B13: 分項加總差異 | C13: 低 | D13: 部分小計與四捨五入明細差1至2元；總表仍依原總價，詳核對表。 | E13: p1、p2–8
A14: 立東營造 | B14: 複價乘算微差 | C14: 低 | D14: 部分複價與顯示數量×單價相差1至10元，可能來自隱藏精度，應請廠商說明。 | E14: p2–5
A15: 三家 | B15: 未列合約條件 | C15: 高 | D15: 確認總工期、付款里程碑、保留款、保固、履約保證、變更計價及物價調整。 | E15: 文件未完整列示

Sheet 三家明細
A2: 報價明細（新臺幣元）
A3: 藍字為原報價數值；空白金額代表未列價。乘算僅供核對，不取代原複價。
A5: 資料ID | B5: 原分類 | C5: 子分類 | D5: 原項次 | E5: 工程項目／規格 | F5: 單位 | G5: 數量 | H5: 原單價 | I5: 原複價 | J5: 數量×單價 | K5: 原複價減乘算 | L5: 品牌／原備註 | M5: PDF頁 | N5: 性質 | O5: 統一比較分類 | P5: 核對說明
A6: dazhan-001 | B6: 假設工程 | D6: A001 | E6: 工務所設備（組合屋）/臨時衛 生設備 | F6: 式 | G6: 1 | H6: 537880 | I6: 537880 | J6: =IF(OR(G6="",H6=""),"",ROUND(G6*H6,0)) -> 537880 | K6: =IF(OR(I6="",J6=""),"",I6-J6) -> 0 | M6: 4 | N6: 工程明細 | O6: 假設工程
A7: dazhan-002 | B7: 假設工程 | D7: A002 | E7: 甲種安全圍籬工程/含工程告 示牌 | F7: 式 | G7: 1 | H7: 733748 | I7: 733748 | J7: =IF(OR(G7="",H7=""),"",ROUND(G7*H7,0)) -> 733748 | K7: =IF(OR(I7="",J7=""),"",I7-J7) -> 0 | M7: 4 | N7: 工程明細 | O7: 假設工程
A8: dazhan-003 | B8: 假設工程 | D8: A003 | E8: 外管臨時水電申請及設備/施 工中水電使用費 | F8: 式 | G8: 1 | H8: 717000 | I8: 717000 | J8: =IF(OR(G8="",H8=""),"",ROUND(G8*H8,0)) -> 717000 | K8: =IF(OR(I8="",J8=""),"",I8-J8) -> 0 | M8: 4 | N8: 工程明細 | O8: 假設工程
A9: dazhan-004 | B9: 假設工程 | D9: A004 | E9: 施工臨時水電設備建置費 | F9: 式 | G9: 1 | H9: 360000 | I9: 360000 | J9: =IF(OR(G9="",H9=""),"",ROUND(G9*H9,0)) -> 360000 | K9: =IF(OR(I9="",J9=""),"",I9-J9) -> 0 | M9: 4 | N9: 工程明細 | O9: 假設工程
A10: dazhan-005 | B10: 假設工程 | D10: A005 | E10: 營建混合廢棄物證明及處理 費 | F10: 式 | G10: 1 | H10: 980100 | I10: 980100 | J10: =IF(OR(G10="",H10=""),"",ROUND(G10*H10,0)) -> 980100 | K10: =IF(OR(I10="",J10=""),"",I10-J10) -> 0 | M10: 4 | N10: 工程明細 | O10: 假設工程
A11: dazhan-006 | B11: 假設工程 | D11: A006 | E11: 公共排水溝及道路修復工程 | F11: 式 | G11: 1 | H11: 140000 | I11: 140000 | J11: =IF(OR(G11="",H11=""),"",ROUND(G11*H11,0)) -> 140000 | K11: =IF(OR(I11="",J11=""),"",I11-J11) -> 0 | M11: 4 | N11: 工程明細 | O11: 假設工程
A12: dazhan-007 | B12: 假設工程 | D12: A007 | E12: 工地保全費用/設備保全 | F12: 式 | G12: 1 | H12: 136200 | I12: 136200 | J12: =IF(OR(G12="",H12=""),"",ROUND(G12*H12,0)) -> 136200 | K12: =IF(OR(I12="",J12=""),"",I12-J12) -> 0 | M12: 4 | N12: 工程明細 | O12: 假設工程
A13: dazhan-008 | B13: 土方工程 | D13: B001 | E13: 現有圍籬、成功二路120巷入 口處鐵皮屋拆除運棄及整地 工程 | F13: 式 | G13: 1 | H13: 426000 | I13: 426000 | J13: =IF(OR(G13="",H13=""),"",ROUND(G13*H13,0)) -> 426000 | K13: =IF(OR(I13="",J13=""),"",I13-J13) -> 0 | M13: 5 | N13: 工程明細 | O13: 土方及結構工程
A14: dazhan-009 | B14: 土方工程 | D14: B002 | E14: 土方開挖 | F14: M3 | G14: 1421.46 | H14: 450 | I14: 639657 | J14: =IF(OR(G14="",H14=""),"",ROUND(G14*H14,0)) -> 639657 | K14: =IF(OR(I14="",J14=""),"",I14-J14) -> 0 | L14: 實方 | M14: 5 | N14: 工程明細 | O14: 土方及結構工程
A15: dazhan-010 | B15: 土方工程 | D15: B003 | E15: 回填土方 | F15: M3 | G15: 1421.46 | H15: 360 | I15: 511726 | J15: =IF(OR(G15="",H15=""),"",ROUND(G15*H15,0)) -> 511726 | K15: =IF(OR(I15="",J15=""),"",I15-J15) -> 0 | L15: 實方/暫置基地內 | M15: 5 | N15: 工程明細 | O15: 土方及結構工程
A16: dazhan-011 | B16: 土方工程 | D16: B004 | E16: 污水處理區土方開挖及回填 工程（二處） | F16: 式 | G16: 1 | H16: 60000 | I16: 60000 | J16: =IF(OR(G16="",H16=""),"",ROUND(G16*H16,0)) -> 60000 | K16: =IF(OR(I16="",J16=""),"",I16-J16) -> 0 | M16: 5 | N16: 工程明細 | O16: 土方及結構工程
A17: dazhan-012 | B17: 鋼構工程 | D17: C001 | E17: SN490B鋼構材料 H型鋼 | F17: 噸 | G17: 366.55 | H17: 31700 | I17: 11619635 | J17: =IF(OR(G17="",H17=""),"",ROUND(G17*H17,0)) -> 11619635 | K17: =IF(OR(I17="",J17=""),"",I17-J17) -> 0 | M17: 6 | N17: 工程明細 | O17: 鋼構工程
A18: dazhan-013 | B18: 鋼構工程 | D18: C002 | E18: SN490B鋼鈑材料 | F18: 噸 | G18: 76.21 | H18: 38200 | I18: 2911222 | J18: =IF(OR(G18="",H18=""),"",ROUND(G18*H18,0)) -> 2911222 | K18: =IF(OR(I18="",J18=""),"",I18-J18) -> 0 | M18: 6 | N18: 工程明細 | O18: 鋼構工程
A19: dazhan-014 | B19: 鋼構工程 | D19: C003 | E19: 廠內加工焊接（含柱封板） | F19: 噸 | G19: 442.76 | H19: 6800 | I19: 3010768 | J19: =IF(OR(G19="",H19=""),"",ROUND(G19*H19,0)) -> 3010768 | K19: =IF(OR(I19="",J19=""),"",I19-J19) -> 0 | M19: 6 | N19: 工程明細 | O19: 鋼構工程
A20: dazhan-015 | B20: 鋼構工程 | D20: C004 | E20: 鋼構噴砂+1道磷酸鋅底漆 | F20: 噸 | G20: 442.76 | H20: 2900 | I20: 1284004 | J20: =IF(OR(G20="",H20=""),"",ROUND(G20*H20,0)) -> 1284004 | K20: =IF(OR(I20="",J20=""),"",I20-J20) -> 0 | M20: 6 | N20: 工程明細 | O20: 鋼構工程
A21: dazhan-016 | B21: 鋼構工程 | D21: C005 | E21: 鋼構運輸 | F21: 噸 | G21: 442.76 | H21: 1700 | I21: 752692 | J21: =IF(OR(G21="",H21=""),"",ROUND(G21*H21,0)) -> 752692 | K21: =IF(OR(I21="",J21=""),"",I21-J21) -> 0 | M21: 6 | N21: 工程明細 | O21: 鋼構工程
A22: dazhan-017 | B22: 鋼構工程 | D22: C006 | E22: 鋼構加工損耗品/五金焊材 | F22: 噸 | G22: 442.76 | H22: 1500 | I22: 664140 | J22: =IF(OR(G22="",H22=""),"",ROUND(G22*H22,0)) -> 664140 | K22: =IF(OR(I22="",J22=""),"",I22-J22) -> 0 | M22: 6 | N22: 工程明細 | O22: 鋼構工程
A23: dazhan-018 | B23: 鋼構工程 | D23: C007 | E23: 鋼構組立吊裝 | F23: 噸 | G23: 442.76 | H23: 6000 | I23: 2656560 | J23: =IF(OR(G23="",H23=""),"",ROUND(G23*H23,0)) -> 2656560 | K23: =IF(OR(I23="",J23=""),"",I23-J23) -> 0 | M23: 6 | N23: 工程明細 | O23: 鋼構工程
A24: dazhan-019 | B24: 鋼構工程 | D24: C008 | E24: 高拉力螺栓 | F24: KG | G24: 4664 | H24: 88 | I24: 410432 | J24: =IF(OR(G24="",H24=""),"",ROUND(G24*H24,0)) -> 410432 | K24: =IF(OR(I24="",J24=""),"",I24-J24) -> 0 | M24: 6 | N24: 工程明細 | O24: 鋼構工程
A25: dazhan-020 | B25: 鋼構工程 | D25: C009 | E25: 鋼承版（3W DECK T=1.2mm） | F25: M2 | G25: 3867.65 | H25: 630 | I25: 2436620 | J25: =IF(OR(G25="",H25=""),"",ROUND(G25*H25,0)) -> 2436620 | K25: =IF(OR(I25="",J25=""),"",I25-J25) -> 0 | M25: 6 | N25: 工程明細 | O25: 鋼構工程
A26: dazhan-021 | B26: 鋼構工程 | D26: C010 | E26: DECK剪力釘（φ19*76L） | F26: 支 | G26: 14673 | H26: 32 | I26: 469536 | J26: =IF(OR(G26="",H26=""),"",ROUND(G26*H26,0)) -> 469536 | K26: =IF(OR(I26="",J26=""),"",I26-J26) -> 0 | M26: 6 | N26: 工程明細 | O26: 鋼構工程
A27: dazhan-022 | B27: 鋼構工程 | D27: C011 | E27: 與RC牆接合剪力釘 | F27: 支 | G27: 9344 | H27: 30 | I27: 280320 | J27: =IF(OR(G27="",H27=""),"",ROUND(G27*H27,0)) -> 280320 | K27: =IF(OR(I27="",J27=""),"",I27-J27) -> 0 | M27: 6 | N27: 工程明細 | O27: 鋼構工程
... A31: dazhan-026 | B31: 鋼構工程 | D31: C015 | E31: 鋼構無收縮水泥灌注 | F31: 處 | G31: 34 | H31: 4500 | I31: 153000 | J31: =IF(OR(G31="",H31=""),"",ROUND(G31*H31,0)) -> 153000 | K31: =IF(OR(I31="",J31=""),"",I31-J31) -> 0 | M31: 6 | N31: 工程明細 | O31: 鋼構工程
A32: dazhan-027 | B32: 鋼構工程 | D32: C016 | E32: 二工鋼構工程 | F32: KG | G32: 4982 | H32: 88 | I32: 438416 | J32: =IF(OR(G32="",H32=""),"",ROUND(G32*H32,0)) -> 438416 | K32: =IF(OR(I32="",J32=""),"",I32-J32) -> 0 | L32: （含廠製.噴砂油 漆.運輸.安裝） | M32: 6 | N32: 工程明細 | O32: 鋼構工程
A33: dazhan-028 | B33: 鋼構工程 | D33: C017 | E33: 二工鋼承版（3W T=1.2mm） | F33: M2 | G33: 144.2 | H33: 830 | I33: 119686 | J33: =IF(OR(G33="",H33=""),"",ROUND(G33*H33,0)) -> 119686 | K33: =IF(OR(I33="",J33=""),"",I33-J33) -> 0 | M33: 6 | N33: 工程明細 | O33: 鋼構工程
A34: dazhan-029 | B34: 鋼構工程 | D34: C018 | E34: 鋼構檢驗 | F34: 噸 | G34: 442.76 | H34: 650 | I34: 287794 | J34: =IF(OR(G34="",H34=""),"",ROUND(G34*H34,0)) -> 287794 | K34: =IF(OR(I34="",J34=""),"",I34-J34) -> 0 | M34: 6 | N34: 工程明細 | O34: 鋼構工程
A35: dazhan-030 | B35: 鋼構工程 | D35: C019 | E35: 鋼構施工圖繪製及安全措施 | F35: 噸 | G35: 442.76 | H35: 1200 | I35: 531312 | J35: =IF(OR(G35="",H35=""),"",ROUND(G35*H35,0)) -> 531312 | K35: =IF(OR(I35="",J35=""),"",I35-J35) -> 0 | M35: 6 | N35: 工程明細 | O35: 鋼構工程
A36: dazhan-031 | B36: 鋼構工程 | D36: C021 | E36: 鋼樑鋼筋焊植工程 | F36: 支 | G36: 4646 | H36: 30 | I36: 139380 | J36: =IF(OR(G36="",H36=""),"",ROUND(G36*H36,0)) -> 139380 | K36: =IF(OR(I36="",J36=""),"",I36-J36) -> 0 | M36: 6 | N36: 工程明細 | O36: 鋼構工程
A37: dazhan-032 | B37: 鋼構工程 | D37: C022 | E37: 鋼柱.鋼樑噴塗防火漆1小時 | F37: M2 | G37: 5731.95 | H37: 265 | I37: 1518967 | J37: =IF(OR(G37="",H37=""),"",ROUND(G37*H37,0)) -> 1518967 | K37: =IF(OR(I37="",J37=""),"",I37-J37) -> 0 | L37: （FM-906）+面漆 （1030FM | M37: 6 | N37: 工程明細 | O37: 鋼構工程
A38: dazhan-033 | B38: 鋼構工程 | D38: C023 | E38: 甲梯/噴塗及手工刷塗面漆 | F38: 座 | G38: 1 | H38: 32000 | I38: 32000 | J38: =IF(OR(G38="",H38=""),"",ROUND(G38*H38,0)) -> 32000 | K38: =IF(OR(I38="",J38=""),"",I38-J38) -> 0 | M38: 6 | N38: 工程明細 | O38: 鋼構工程
A39: dazhan-034 | B39: 鋼構工程 | D39: C024 | E39: 乙梯/噴塗及手工刷塗面漆 | F39: 座 | G39: 1 | H39: 46000 | I39: 46000 | J39: =IF(OR(G39="",H39=""),"",ROUND(G39*H39,0)) -> 46000 | K39: =IF(OR(I39="",J39=""),"",I39-J39) -> 0 | M39: 6 | N39: 工程明細 | O39: 鋼構工程
A40: dazhan-035 | B40: 鋼構工程 | D40: C025 | E40: 剪刀式高空作業車 | F40: 式 | G40: 1 | H40: 80000 | I40: 80000 | J40: =IF(OR(G40="",H40=""),"",ROUND(G40*H40,0)) -> 80000 | K40: =IF(OR(I40="",J40=""),"",I40-J40) -> 0 | L40: 4台 | M40: 6 | N40: 工程明細 | O40: 鋼構工程
A41: dazhan-036 | B41: 結構工程 | D41: D001 | E41: 鋼筋加工及組立SD280 #3 | F41: T | G41: 96.04 | H41: 27900 | I41: 2679516 | J41: =IF(OR(G41="",H41=""),"",ROUND(G41*H41,0)) -> 2679516 | K41: =IF(OR(I41="",J41=""),"",I41-J41) -> 0 | L41: 非水淬 | M41: 7 | N41: 工程明細 | O41: 土方及結構工程
A42: dazhan-037 | B42: 結構工程 | D42: D002 | E42: 鋼筋加工及組立 SD420W/#4（含）以上 | F42: T | G42: 252.07 | H42: 28700 | I42: 7234409 | J42: =IF(OR(G42="",H42=""),"",ROUND(G42*H42,0)) -> 7234409 | K42: =IF(OR(I42="",J42=""),"",I42-J42) -> 0 | M42: 7 | N42: 工程明細 | O42: 土方及結構工程
A43: dazhan-038 | B43: 結構工程 | D43: D003 | E43: 鋼梯點焊鋼絲網舖設工程 | F43: M2 | G43: 70.91 | H43: 306 | I43: 21698 | J43: =IF(OR(G43="",H43=""),"",ROUND(G43*H43,0)) -> 21698 | K43: =IF(OR(I43="",J43=""),"",I43-J43) -> 0 | M43: 7 | N43: 工程明細 | O43: 土方及結構工程
A44: dazhan-039 | B44: 結構工程 | D44: D004 | E44: 預拌混凝土及澆置 2000PSI | F44: M3 | G44: 286.35 | H44: 2940 | I44: 841869 | J44: =IF(OR(G44="",H44=""),"",ROUND(G44*H44,0)) -> 841869 | K44: =IF(OR(I44="",J44=""),"",I44-J44) -> 0 | L44: 台鋼 | M44: 7 | N44: 工程明細 | O44: 土方及結構工程
A45: dazhan-040 | B45: 結構工程 | D45: D005 | E45: 預拌混凝土及澆置 4000PSI | F45: M3 | G45: 2747.47 | H45: 3240 | I45: 8901803 | J45: =IF(OR(G45="",H45=""),"",ROUND(G45*H45,0)) -> 8901803 | K45: =IF(OR(I45="",J45=""),"",I45-J45) -> 0 | L45: 亞泥 | M45: 7 | N45: 工程明細 | O45: 土方及結構工程
...

Sheet 原報價總表
A2: 原總表與來源資料
A5: 廠商 | B5: 報價日期 | C5: 原報價總額 | D5: 稅前合計 | E5: 原營業稅 | F5: 原空污費 | G5: 工程小計 | H5: 費用／稅列項加總 | I5: 逐筆明細加總 | J5: 明細減總額 | K5: 來源PDF | L5: 日期與面積註記
A6: 大展營造 | B6: 2026-09-30 | C6: 141502803 | D6: 134764574 | E6: 6738229 | G6: 117847648 | H6: 141502803 | I6: =SUM(三家明細!I6:I232) -> 141502803 | J6: =I6-C6 -> 0 | K6: 115.09.30-大展營造-工程估價書.pdf | L6: PDF首頁115/09/30；首頁列建築面積1189.5坪 1189.5坪。不同面積口徑，不做每坪排名。
A7: 立東營造 | B7: 2026-10-01 | C7: 143400000 | D7: 136571429 | E7: 6828571 | G7: 121989307 | H7: 143400000 | I7: =SUM(三家明細!I233:I420) -> 143400000 | J7: =I7-C7 -> 0 | K7: 立東營造115-12.瓏昇廠房新建廠房案-估價單(加入使用品牌)_115.10.01.pdf | L7: 日期依檔名115.10.01；PDF內未見日期；假設工程清潔計價面積，非確認的總樓地板面積 1244.5坪。不同面積口徑，不做每坪排名。
A8: 基益營造 | B8: 2026-04-01 | C8: 210047839 | D8: 199983656 | E8: 9999183 | F8: 65000 | G8: 182967664 | H8: 210047839 | I8: =SUM(三家明細!I421:I611) -> 210047840 | J8: =I8-C8 -> 1 | K8: 115.04.01-基益營造-工程估價單.pdf | L8: PDF日期2026/4/1；假設工程清潔計價面積，非確認的總樓地板面積 1182.89坪。不同面積口徑，不做每坪排名。
A12: 廠商 | B12: 原分類 | C12: 原金額 | D12: PDF頁 | E12: 註記
A13: 大展營造 | B13: 假設工程 | C13: 3604928 | D13: 1 | E13: 總表原值；不得與逐筆明細再重複加總
A14: 大展營造 | B14: 土方工程 | C14: 1637383 | D14: 1 | E14: 總表原值；不得與逐筆明細再重複加總
A15: 大展營造 | B15: 鋼構工程 | C15: 31302484 | D15: 1 | E15: 總表原值；不得與逐筆明細再重複加總
A16: 大展營造 | B16: 結構工程 | C16: 38156185 | D16: 1 | E16: 總表原值；不得與逐筆明細再重複加總
A17: 大展營造 | B17: 內部裝修工程 | C17: 20184097 | D17: 1 | E17: 總表原值；不得與逐筆明細再重複加總
A18: 大展營造 | B18: 外部裝修工程 | C18: 12011044 | D18: 1 | E18: 總表原值；不得與逐筆明細再重複加總
A19: 大展營造 | B19: 門窗工程 | C19: 7140806 | D19: 1 | E19: 總表原值；不得與逐筆明細再重複加總
A20: 大展營造 | B20: 裝修什項工程 | C20: 1096267 | D20: 1 | E20: 總表原值；不得與逐筆明細再重複加總
A21: 大展營造 | B21: 公共設施工程 | C21: 2714454 | D21: 1 | E21: 總表原值；不得與逐筆明細再重複加總
A22: 大展營造 | B22: 運什費 | C22: 3605864 | D22: 1 | E22: 總表原值；不得與逐筆明細再重複加總
A23: 大展營造 | B23: 管理費 | C23: 11319467 | D23: 1 | E23: 總表原值；不得與逐筆明細再重複加總
A24: 大展營造 | B24: 利潤及稅捐 | C24: 8729824 | D24: 1 | E24: 總表原值；不得與逐筆明細再重複加總
... A49: 基益營造 | B49: 空氣污染防治費 | C49: 65000 | D49: 1 | E49: 總表原值；不得與逐筆明細再重複加總
