Workbook

Sheet 報價總覽
A2: 基益營造工程報價整理
A3: 新臺幣元。原分類與費用完整保留；明細可篩選並追溯PDF頁碼。
A5: 原總表分類 | B5: 原列金額 | C5: 明細彙總 | D5: 彙總減原列 | E5: 說明
A6: 假設工程 | B6: 6917256 | C6: =SUMIFS(報價明細!$I$6:$I$196,報價明細!$B$6:$B$196,A6) -> 6917256 | D6: =C6-B6 -> 0
A7: 結構工程 | B7: 63168038 | C7: =SUMIFS(報價明細!$I$6:$I$196,報價明細!$B$6:$B$196,A7) -> 63168038 | D7: =C7-B7 -> 0
A8: 鋼構工程 | B8: 41869118 | C8: =SUMIFS(報價明細!$I$6:$I$196,報價明細!$B$6:$B$196,A8) -> 41869118 | D8: =C8-B8 -> 0
A9: 泥作裝修工程 | B9: 41094488 | C9: =SUMIFS(報價明細!$I$6:$I$196,報價明細!$B$6:$B$196,A9) -> 41094489 | D9: =C9-B9 -> 1
A10: 外部裝修工程 | B10: 13066593 | C10: =SUMIFS(報價明細!$I$6:$I$196,報價明細!$B$6:$B$196,A10) -> 13066593 | D10: =C10-B10 -> 0
A11: 門窗工程 | B11: 7371886 | C11: =SUMIFS(報價明細!$I$6:$I$196,報價明細!$B$6:$B$196,A11) -> 7371886 | D11: =C11-B11 -> 0
A12: 設備工程 | B12: 4693000 | C12: =SUMIFS(報價明細!$I$6:$I$196,報價明細!$B$6:$B$196,A12) -> 4693000 | D12: =C12-B12 -> 0
A13: 雜項工程 | B13: 2937300 | C13: =SUMIFS(報價明細!$I$6:$I$196,報價明細!$B$6:$B$196,A13) -> 2937300 | D13: =C13-B13 -> 0
A14: 綠化植栽工程 | B14: 1849985 | C14: =SUMIFS(報價明細!$I$6:$I$196,報價明細!$B$6:$B$196,A14) -> 1849985 | D14: =C14-B14 -> 0
A15: 勞工安全衛生管理費（0.8%） | B15: 1463741 | C15: =SUMIFS(報價明細!$I$6:$I$196,報價明細!$B$6:$B$196,A15) -> 1463741 | D15: =C15-B15 -> 0
A16: 工程營造保險費（0.5%） | B16: 914838 | C16: =SUMIFS(報價明細!$I$6:$I$196,報價明細!$B$6:$B$196,A16) -> 914838 | D16: =C16-B16 -> 0
A17: 管理費及利潤（8%） | B17: 14637413 | C17: =SUMIFS(報價明細!$I$6:$I$196,報價明細!$B$6:$B$196,A17) -> 14637413 | D17: =C17-B17 -> 0
... A19: 空氣污染防治費 | B19: 65000 | C19: =SUMIFS(報價明細!$I$6:$I$196,報價明細!$B$6:$B$196,A19) -> 65000 | D19: =C19-B19 -> 0
A21: 原報價總計 | B21: 210047839 | C21: =SUM(報價明細!I6:I196) -> 210047840 | D21: =C21-B21 -> 1 | E21: 原總價保留，不以重算結果覆蓋
A22: 稅前合計 | B22: 199983656 | E22: 不含營業稅；基益另列空污費
A23: 營業稅 | B23: 9999183 | E23: 原報價稅額
A24: 空污費 | B24: 65000 | E24: 是否包含及課稅口徑依原單
A25: 報價日期 | B25: 2026-04-01 | E25: PDF日期2026/4/1
A26: 有效期限 | B26: 文件未列 | E26: 原報價條件
A27: 明細筆數 | B27: 191 | E27: 含明細及僅在總表列示的費用
A29: 報價日期較另兩家早約半年，數量與部分規格差異大，須確認圖說版本及重報價。
A31: 核對採原單顯示數量及單價四捨五入至元；小額差異可能源自底層精度。
A34: 原分項小計（不再加總） | B34: 原列金額 | C34: 明細彙總 | D34: 彙總減原列 | E34: 分類／PDF頁
A35: 防水，屋面工程 | B35: 3830976 | C35: =SUMIFS(報價明細!$I$6:$I$196,報價明細!$B$6:$B$196,"泥作裝修工程",報價明細!$C$6:$C$196,"防水，屋面工程") -> 3830976 | D35: =C35-B35 -> 0 | E35: 泥作裝修工程／p4
A36: 室內地坪工程 | B36: 13750957 | C36: =SUMIFS(報價明細!$I$6:$I$196,報價明細!$B$6:$B$196,"泥作裝修工程",報價明細!$C$6:$C$196,"室內地坪工程") -> 13750957 | D36: =C36-B36 -> 0 | E36: 泥作裝修工程／p4
A37: 室內牆面工程 | B37: 21078914 | C37: =SUMIFS(報價明細!$I$6:$I$196,報價明細!$B$6:$B$196,"泥作裝修工程",報價明細!$C$6:$C$196,"室內牆面工程") -> 21078914 | D37: =C37-B37 -> 0 | E37: 泥作裝修工程／p5
A38: 室內平頂工程 | B38: 2433641 | C38: =SUMIFS(報價明細!$I$6:$I$196,報價明細!$B$6:$B$196,"泥作裝修工程",報價明細!$C$6:$C$196,"室內平頂工程") -> 2433642 | D38: =C38-B38 -> 1 | E38: 泥作裝修工程／p5
A39: 門窗工程本體 | B39: 5710846 | C39: =SUM(報價明細!I107,報價明細!I108,報價明細!I109,報價明細!I110,報價明細!I111,報價明細!I112,報價明細!I113,報價明細!I114,報價明細!I115,報價明細!I116,報價明細!I117,報價明細!I118,報價明細!I119,報價明細!I120,報價明細!I121,報價明細!I122,報價明細!I123,報價明細!I124,報價明細!I125,報價明細!I126,報價明細!I127,報價明細!I128,報價明細!I129,報價明細!I130,報價明細!I131,報價明細!I132,報價明細!I133,報價明細!I134,報價明細!I135,報價明細!I136,報價明細!I137,報價明細!I138,報價明細!I139,報價明細!I140,報價明細!I141,報價明細!I142,報價明細!I143,報價明細!I144,報價明細!I145,報價明細!I146,報價明細!I147,報價明細!I148,報價明細!I149,報價明細!I150,報價明細!I151) -> 5710846 | D39: =C39-B39 -> 0 | E39: 門窗工程／p7
A40: 玻璃工程 | B40: 592809 | C40: =SUMIFS(報價明細!$I$6:$I$196,報價明細!$B$6:$B$196,"門窗工程",報價明細!$C$6:$C$196,"玻璃工程") -> 592809 | D40: =C40-B40 -> 0 | E40: 門窗工程／p7
A41: 崁縫工程 | B41: 841325 | C41: =SUMIFS(報價明細!$I$6:$I$196,報價明細!$B$6:$B$196,"門窗工程",報價明細!$C$6:$C$196,"崁縫工程") -> 841325 | D41: =C41-B41 -> 0 | E41: 門窗工程／p7
A42: Silicone工程 | B42: 226906 | C42: =SUMIFS(報價明細!$I$6:$I$196,報價明細!$B$6:$B$196,"門窗工程",報價明細!$C$6:$C$196,"Silicone工程") -> 226906 | D42: =C42-B42 -> 0 | E42: 門窗工程／p7
A43: 總表附加費小計 | B43: 17015993 | C43: =SUM(B15:B17) -> 17015992 | D43: =C43-B43 -> -1 | E43: 安衛＋保險＋管理利潤；原小計比三筆加總多1元

Sheet 報價明細
A2: 報價明細（新臺幣元）
A3: 藍字為原報價數值；空白金額代表未列價。乘算僅供核對，不取代原複價。
A5: 資料ID | B5: 原分類 | C5: 子分類 | D5: 原項次 | E5: 工程項目／規格 | F5: 單位 | G5: 數量 | H5: 原單價 | I5: 原複價 | J5: 數量×單價 | K5: 原複價減乘算 | L5: 品牌／原備註 | M5: PDF頁 | N5: 性質 | O5: 統一比較分類 | P5: 核對說明
A6: jiyi-001 | B6: 假設工程 | D6: 1 | E6: 基地整地及廢物運棄 | F6: 式 | G6: 1 | H6: 120000 | I6: 120000 | J6: =IF(OR(G6="",H6=""),"",ROUND(G6*H6,0)) -> 120000 | K6: =IF(OR(I6="",J6=""),"",I6-J6) -> 0 | M6: 2 | N6: 工程明細 | O6: 假設工程
A7: jiyi-002 | B7: 假設工程 | D7: 2 | E7: 工地施工圍籬（含防溢座及噴漆） | F7: M | G7: 308.81 | H7: 1850 | I7: 571299 | J7: =IF(OR(G7="",H7=""),"",ROUND(G7*H7,0)) -> 571299 | K7: =IF(OR(I7="",J7=""),"",I7-J7) -> 0 | M7: 2 | N7: 工程明細 | O7: 假設工程
A8: jiyi-003 | B8: 假設工程 | D8: 3 | E8: 工.地進出活動大門 | F8: 座 | G8: 1 | H8: 25000 | I8: 25000 | J8: =IF(OR(G8="",H8=""),"",ROUND(G8*H8,0)) -> 25000 | K8: =IF(OR(I8="",J8=""),"",I8-J8) -> 0 | M8: 2 | N8: 工程明細 | O8: 假設工程
A9: jiyi-004 | B9: 假設工程 | D9: 4 | E9: 安全警示燈、工地安全守則、工程告示牌 | F9: 式 | G9: 1 | H9: 15000 | I9: 15000 | J9: =IF(OR(G9="",H9=""),"",ROUND(G9*H9,0)) -> 15000 | K9: =IF(OR(I9="",J9=""),"",I9-J9) -> 0 | M9: 2 | N9: 工程明細 | O9: 假設工程
A10: jiyi-005 | B10: 假設工程 | D10: 5 | E10: 臨時活動廁所 | F10: 座 | G10: 2 | H10: 15000 | I10: 30000 | J10: =IF(OR(G10="",H10=""),"",ROUND(G10*H10,0)) -> 30000 | K10: =IF(OR(I10="",J10=""),"",I10-J10) -> 0 | M10: 2 | N10: 工程明細 | O10: 假設工程
A11: jiyi-006 | B11: 假設工程 | D11: 6 | E11: 申請臨時水，電及工地配管、拉線費 | F11: 式 | G11: 1 | J11: =IF(OR(G11="",H11=""),"",ROUND(G11*H11,0)) | K11: =IF(OR(I11="",J11=""),"",I11-J11) | L11: 威向水電 | M11: 2 | N11: 工程明細 | O11: 假設工程 | P11: 原單未列金額；不視為零元或已含。
A12: jiyi-007 | B12: 假設工程 | D12: 7 | E12: 臨時水及通訊.電費使用費 | F12: 月 | G12: 1 | J12: =IF(OR(G12="",H12=""),"",ROUND(G12*H12,0)) | K12: =IF(OR(I12="",J12=""),"",I12-J12) | L12: 業主自理 | M12: 2 | N12: 工程明細 | O12: 假設工程 | P12: 原單未列金額；不視為零元或已含。
A13: jiyi-008 | B13: 假設工程 | D13: 8 | E13: 結構體完成/完工交屋 清潔費 | F13: 建坪 | G13: 1182.89 | H13: 500 | I13: 591445 | J13: =IF(OR(G13="",H13=""),"",ROUND(G13*H13,0)) -> 591445 | K13: =IF(OR(I13="",J13=""),"",I13-J13) -> 0 | M13: 2 | N13: 工程明細 | O13: 假設工程
A14: jiyi-009 | B14: 假設工程 | D14: 9 | E14: 外觀及交屋清潔費 | F14: 建坪 | G14: 1182.89 | H14: 350 | I14: 414012 | J14: =IF(OR(G14="",H14=""),"",ROUND(G14*H14,0)) -> 414012 | K14: =IF(OR(I14="",J14=""),"",I14-J14) -> 0 | M14: 2 | N14: 工程明細 | O14: 假設工程
A15: jiyi-010 | B15: 假設工程 | D15: 10 | E15: 週邊環境公共設施維護費 | F15: 式 | G15: 1 | H15: 80000 | I15: 80000 | J15: =IF(OR(G15="",H15=""),"",ROUND(G15*H15,0)) -> 80000 | K15: =IF(OR(I15="",J15=""),"",I15-J15) -> 0 | M15: 2 | N15: 工程明細 | O15: 假設工程
A16: jiyi-011 | B16: 假設工程 | D16: 11 | E16: 垃圾管道 | F16: 式 | G16: 1 | H16: 50000 | I16: 50000 | J16: =IF(OR(G16="",H16=""),"",ROUND(G16*H16,0)) -> 50000 | K16: =IF(OR(I16="",J16=""),"",I16-J16) -> 0 | M16: 2 | N16: 工程明細 | O16: 假設工程
A17: jiyi-012 | B17: 假設工程 | D17: 12 | E17: 臨時道路補修及維護 | F17: 式 | G17: 1 | H17: 150000 | I17: 150000 | J17: =IF(OR(G17="",H17=""),"",ROUND(G17*H17,0)) -> 150000 | K17: =IF(OR(I17="",J17=""),"",I17-J17) -> 0 | M17: 2 | N17: 工程明細 | O17: 假設工程
A18: jiyi-013 | B18: 假設工程 | D18: 13 | E18: 勘驗/竣工圖繪製/使用執照申請費 | F18: 式 | G18: 1 | H18: 500000 | I18: 500000 | J18: =IF(OR(G18="",H18=""),"",ROUND(G18*H18,0)) -> 500000 | K18: =IF(OR(I18="",J18=""),"",I18-J18) -> 0 | M18: 2 | N18: 工程明細 | O18: 假設工程
A19: jiyi-014 | B19: 假設工程 | D19: 14 | E19: 開工、上樑、各式典禮及其他未列之雜項費用 | F19: 式 | G19: 1 | H19: 300000 | I19: 300000 | J19: =IF(OR(G19="",H19=""),"",ROUND(G19*H19,0)) -> 300000 | K19: =IF(OR(I19="",J19=""),"",I19-J19) -> 0 | M19: 2 | N19: 工程明細 | O19: 假設工程
A20: jiyi-015 | B20: 假設工程 | D20: 15 | E20: 營造廠技師現場勘驗簽証費 | F20: 次 | G20: 5 | H20: 15000 | I20: 75000 | J20: =IF(OR(G20="",H20=""),"",ROUND(G20*H20,0)) -> 75000 | K20: =IF(OR(I20="",J20=""),"",I20-J20) -> 0 | M20: 2 | N20: 工程明細 | O20: 假設工程
A21: jiyi-016 | B21: 假設工程 | D21: 16 | E21: 建築物營建廢棄物處理費 | F21: M3 | G21: 485 | H21: 4500 | I21: 2182500 | J21: =IF(OR(G21="",H21=""),"",ROUND(G21*H21,0)) -> 2182500 | K21: =IF(OR(I21="",J21=""),"",I21-J21) -> 0 | M21: 2 | N21: 工程明細 | O21: 假設工程
A22: jiyi-017 | B22: 假設工程 | D22: 17 | E22: 建築物營建廢棄物申報/完工證明 | F22: M3 | G22: 485 | H22: 800 | I22: 388000 | J22: =IF(OR(G22="",H22=""),"",ROUND(G22*H22,0)) -> 388000 | K22: =IF(OR(I22="",J22=""),"",I22-J22) -> 0 | L22: 含規費 | M22: 2 | N22: 工程明細 | O22: 假設工程
A23: jiyi-018 | B23: 假設工程 | D23: 18 | E23: 逕流廢水申報 | F23: 式 | G23: 1 | H23: 75000 | I23: 75000 | J23: =IF(OR(G23="",H23=""),"",ROUND(G23*H23,0)) -> 75000 | K23: =IF(OR(I23="",J23=""),"",I23-J23) -> 0 | L23: 含規費 | M23: 2 | N23: 工程明細 | O23: 假設工程
A24: jiyi-019 | B24: 假設工程 | D24: 19 | E24: 工務所設置及雜支 | F24: 式 | G24: 1 | H24: 350000 | I24: 350000 | J24: =IF(OR(G24="",H24=""),"",ROUND(G24*H24,0)) -> 350000 | K24: =IF(OR(I24="",J24=""),"",I24-J24) -> 0 | M24: 2 | N24: 工程明細 | O24: 假設工程
A25: jiyi-020 | B25: 假設工程 | D25: 20 | E25: 品管及材料試驗費 | F25: 式 | G25: 1 | H25: 250000 | I25: 250000 | J25: =IF(OR(G25="",H25=""),"",ROUND(G25*H25,0)) -> 250000 | K25: =IF(OR(I25="",J25=""),"",I25-J25) -> 0 | M25: 2 | N25: 工程明細 | O25: 假設工程
A26: jiyi-021 | B26: 假設工程 | D26: 21 | E26: 臨時工 | F26: 式 | G26: 1 | H26: 750000 | I26: 750000 | J26: =IF(OR(G26="",H26=""),"",ROUND(G26*H26,0)) -> 750000 | K26: =IF(OR(I26="",J26=""),"",I26-J26) -> 0 | M26: 2 | N26: 工程明細 | O26: 假設工程
A27: jiyi-022 | B27: 結構工程 | D27: 1 | E27: 放様 | F27: M2 | G27: 3903.5 | H27: 75 | I27: 292763 | J27: =IF(OR(G27="",H27=""),"",ROUND(G27*H27,0)) -> 292763 | K27: =IF(OR(I27="",J27=""),"",I27-J27) -> 0 | M27: 2 | N27: 工程明細 | O27: 土方及結構工程
A28: jiyi-023 | B28: 結構工程 | D28: 2 | E28: 挖土方 | F28: M3 | G28: 4485 | H28: 285 | I28: 1278225 | J28: =IF(OR(G28="",H28=""),"",ROUND(G28*H28,0)) -> 1278225 | K28: =IF(OR(I28="",J28=""),"",I28-J28) -> 0 | M28: 2 | N28: 工程明細 | O28: 土方及結構工程
A29: jiyi-024 | B29: 結構工程 | D29: 3 | E29: 2000PSI預拌混凝土壓送澆築 | F29: M3 | G29: 425 | H29: 3000 | I29: 1275000 | J29: =IF(OR(G29="",H29=""),"",ROUND(G29*H29,0)) -> 1275000 | K29: =IF(OR(I29="",J29=""),"",I29-J29) -> 0 | M29: 2 | N29: 工程明細 | O29: 土方及結構工程
A30: jiyi-025 | B30: 結構工程 | D30: 4 | E30: 回填土夯實 | F30: M3 | G30: 3250 | H30: 285 | I30: 926250 | J30: =IF(OR(G30="",H30=""),"",ROUND(G30*H30,0)) -> 926250 | K30: =IF(OR(I30="",J30=""),"",I30-J30) -> 0 | M30: 2 | N30: 工程明細 | O30: 土方及結構工程
A31: jiyi-026 | B31: 結構工程 | D31: 5 | E31: 系統模板組立及拆除 | F31: M2 | G31: 9185 | H31: 1450 | I31: 13318250 | J31: =IF(OR(G31="",H31=""),"",ROUND(G31*H31,0)) -> 13318250 | K31: =IF(OR(I31="",J31=""),"",I31-J31) -> 0 | M31: 2 | N31: 工程明細 | O31: 土方及結構工程
A32: jiyi-027 | B32: 結構工程 | D32: 6 | E32: 普通模板及清水模板 | F32: M2 | G32: 3525 | H32: 1000 | I32: 3525000 | J32: =IF(OR(G32="",H32=""),"",ROUND(G32*H32,0)) -> 3525000 | K32: =IF(OR(I32="",J32=""),"",I32-J32) -> 0 | M32: 2 | N32: 工程明細 | O32: 土方及結構工程
A33: jiyi-028 | B33: 結構工程 | D33: 7 | E33: 普通鋼筋及彎紮組立SD280（#3-#5） | F33: 噸 | G33: 648 | H33: 30100 | I33: 19504800 | J33: =IF(OR(G33="",H33=""),"",ROUND(G33*H33,0)) -> 19504800 | K33: =IF(OR(I33="",J33=""),"",I33-J33) -> 0 | M33: 2 | N33: 工程明細 | O33: 土方及結構工程
A34: jiyi-029 | B34: 結構工程 | D34: 8 | E34: 高拉力鋼筋及彎紮組立SD420w（#6-#11） | F34: 噸 | G34: 335 | H34: 32000 | I34: 10720000 | J34: =IF(OR(G34="",H34=""),"",ROUND(G34*H34,0)) -> 10720000 | K34: =IF(OR(I34="",J34=""),"",I34-J34) -> 0 | M34: 2 | N34: 工程明細 | O34: 土方及結構工程
A35: jiyi-030 | B35: 結構工程 | D35: 9 | E35: 4000PSI預拌混凝土壓送澆築 | F35: M3 | G35: 1795 | H35: 3850 | I35: 6910750 | J35: =IF(OR(G35="",H35=""),"",ROUND(G35*H35,0)) -> 6910750 | K35: =IF(OR(I35="",J35=""),"",I35-J35) -> 0 | M35: 2 | N35: 工程明細 | O35: 土方及結構工程
... A38: jiyi-033 | B38: 結構工程 | D38: 12 | E38: 1F機台個別結構體（3M*3M*2M） | F38: 座 | G38: 13 | H38: 145000 | I38: 1885000 | J38: =IF(OR(G38="",H38=""),"",ROUND(G38*H38,0)) -> 1885000 | K38: =IF(OR(I38="",J38=""),"",I38-J38) -> 0 | M38: 3 | N38: 工程明細 | O38: 土方及結構工程
A39: jiyi-034 | B39: 鋼構工程 | D39: 1 | E39: H型鋼 | F39: KG | G39: 395784 | H39: 30 | I39: 11873520 | J39: =IF(OR(G39="",H39=""),"",ROUND(G39*H39,0)) -> 11873520 | K39: =IF(OR(I39="",J39=""),"",I39-J39) -> 0 | L39: SN490YB | M39: 3 | N39: 工程明細 | O39: 鋼構工程
A40: jiyi-035 | B40: 鋼構工程 | D40: 2 | E40: 鐵板接合板加勁板 | F40: KG | G40: 35876 | H40: 38 | I40: 1363288 | J40: =IF(OR(G40="",H40=""),"",ROUND(G40*H40,0)) -> 1363288 | K40: =IF(OR(I40="",J40=""),"",I40-J40) -> 0 | L40: SN490YB | M40: 3 | N40: 工程明細 | O40: 鋼構工程
A41: jiyi-036 | B41: 鋼構工程 | D41: 3 | E41: 柱封板 | F41: KG | G41: 51103 | H41: 39 | I41: 1993017 | J41: =IF(OR(G41="",H41=""),"",ROUND(G41*H41,0)) -> 1993017 | K41: =IF(OR(I41="",J41=""),"",I41-J41) -> 0 | L41: SN491YB（原文如此，牌號待確認） | M41: 3 | N41: 工程明細 | O41: 鋼構工程
A42: jiyi-037 | B42: 鋼構工程 | D42: 4 | E42: 鋼梯鐵板 | F42: KG | G42: 11131 | H42: 32 | I42: 356192 | J42: =IF(OR(G42="",H42=""),"",ROUND(G42*H42,0)) -> 356192 | K42: =IF(OR(I42="",J42=""),"",I42-J42) -> 0 | L42: A36 | M42: 3 | N42: 工程明細 | O42: 鋼構工程
A43: jiyi-038 | B43: 鋼構工程 | D43: 5 | E43: 運輸 | F43: KG | G43: 493894 | H43: 1 | I43: 493894 | J43: =IF(OR(G43="",H43=""),"",ROUND(G43*H43,0)) -> 493894 | K43: =IF(OR(I43="",J43=""),"",I43-J43) -> 0 | M43: 3 | N43: 工程明細 | O43: 鋼構工程
A44: jiyi-039 | B44: 鋼構工程 | D44: 6 | E44: 塗裝-噴砂一底一面 | F44: KG | G44: 493894 | H44: 3.2 | I44: 1580461 | J44: =IF(OR(G44="",H44=""),"",ROUND(G44*H44,0)) -> 1580461 | K44: =IF(OR(I44="",J44=""),"",I44-J44) -> 0 | L44: #36灰 | M44: 3 | N44: 工程明細 | O44: 鋼構工程
...

Sheet 備註與來源
A2: 來源與報價條款
A5: PDF頁 | B5: 內容類型 | C5: 原文／整理說明
B6: 來源PDF | C6: 115.04.01-基益營造-工程估價單.pdf
B7: 提供文件頁數 | C7: 8
B8: 整理原則 | C8: 原複價為分析基礎；未列價不當零元；數量×單價僅供核對。
A9: 1 | B9: 文件與整理方式 | C9: 報價日期較另兩家早約半年，數量與部分規格差異大，須確認圖說版本及重報價。 原始PDF保留；金額以原複價為準，乘算差額另列。
