Workbook

Sheet 報價總覽
A2: 大展營造工程報價整理
A3: 新臺幣元。原分類與費用完整保留；明細可篩選並追溯PDF頁碼。
A5: 原總表分類 | B5: 原列金額 | C5: 明細彙總 | D5: 彙總減原列 | E5: 說明
A6: 假設工程 | B6: 3604928 | C6: =SUMIFS(報價明細!$I$6:$I$232,報價明細!$B$6:$B$232,A6) -> 3604928 | D6: =C6-B6 -> 0
A7: 土方工程 | B7: 1637383 | C7: =SUMIFS(報價明細!$I$6:$I$232,報價明細!$B$6:$B$232,A7) -> 1637383 | D7: =C7-B7 -> 0
A8: 鋼構工程 | B8: 31302484 | C8: =SUMIFS(報價明細!$I$6:$I$232,報價明細!$B$6:$B$232,A8) -> 31302484 | D8: =C8-B8 -> 0
A9: 結構工程 | B9: 38156185 | C9: =SUMIFS(報價明細!$I$6:$I$232,報價明細!$B$6:$B$232,A9) -> 38156185 | D9: =C9-B9 -> 0
A10: 內部裝修工程 | B10: 20184097 | C10: =SUMIFS(報價明細!$I$6:$I$232,報價明細!$B$6:$B$232,A10) -> 20184097 | D10: =C10-B10 -> 0
A11: 外部裝修工程 | B11: 12011044 | C11: =SUMIFS(報價明細!$I$6:$I$232,報價明細!$B$6:$B$232,A11) -> 12011044 | D11: =C11-B11 -> 0
A12: 門窗工程 | B12: 7140806 | C12: =SUMIFS(報價明細!$I$6:$I$232,報價明細!$B$6:$B$232,A12) -> 7140806 | D12: =C12-B12 -> 0
A13: 裝修什項工程 | B13: 1096267 | C13: =SUMIFS(報價明細!$I$6:$I$232,報價明細!$B$6:$B$232,A13) -> 1096267 | D13: =C13-B13 -> 0
A14: 公共設施工程 | B14: 2714454 | C14: =SUMIFS(報價明細!$I$6:$I$232,報價明細!$B$6:$B$232,A14) -> 2714454 | D14: =C14-B14 -> 0
A15: 運什費 | B15: 3605864 | C15: =SUMIFS(報價明細!$I$6:$I$232,報價明細!$B$6:$B$232,A15) -> 3605864 | D15: =C15-B15 -> 0
A16: 管理費 | B16: 11319467 | C16: =SUMIFS(報價明細!$I$6:$I$232,報價明細!$B$6:$B$232,A16) -> 11319467 | D16: =C16-B16 -> 0
A17: 利潤及稅捐 | B17: 8729824 | C17: =SUMIFS(報價明細!$I$6:$I$232,報價明細!$B$6:$B$232,A17) -> 8729824 | D17: =C17-B17 -> 0
A19: 原報價總計 | B19: 141502803 | C19: =SUM(報價明細!I6:I232) -> 141502803 | D19: =C19-B19 -> 0 | E19: 原總價保留，不以重算結果覆蓋
A20: 稅前合計 | B20: 134764574 | E20: 不含營業稅；基益另列空污費
A21: 營業稅 | B21: 6738229 | E21: 原報價稅額
A22: 空污費 | B22: 未列價／業主負擔 | E22: 是否包含及課稅口徑依原單
A23: 報價日期 | B23: 2026-09-30 | E23: PDF首頁115/09/30
A24: 有效期限 | B24: 自報價日起7天 | E24: 原報價條件
A25: 明細筆數 | B25: 227 | E25: 含明細及僅在總表列示的費用
A27: PDF實際20頁，頁首標示共41頁；本次已整理提供的20頁，須確認是否尚有附件。
A29: 核對採原單顯示數量及單價四捨五入至元；小額差異可能源自底層精度。
A32: 原分項小計（不再加總） | B32: 原列金額 | C32: 明細彙總 | D32: 彙總減原列 | E32: 分類／PDF頁

Sheet 報價明細
A2: 報價明細（新臺幣元）
A3: 藍字為原報價數值；空白金額代表未列價。乘算僅供核對，不取代原複價。
A5: 資料ID | B5: 原分類 | C5: 子分類 | D5: 原項次 | E5: 工程項目／規格 | F5: 單位 | G5: 數量 | H5: 原單價 | I5: 原複價 | J5: 數量×單價 | K5: 原複價減乘算 | L5: 品牌／原備註 | M5: PDF頁 | N5: 性質 | O5: 統一比較分類 | P5: 核對說明
A6: dazhan-001 | B6: 假設工程 | D6: A001 | E6: 工務所設備（組合屋）/臨時衛 生設備 | F6: 式 | G6: 1 | H6: 537880 | I6: 537880 | J6: =IF(OR(G6="",H6=""),"",ROUND(G6*H6,0)) -> 537880 | K6: =IF(OR(I6="",J6=""),"",I6-J6) -> 0 | M6: 4 | N6: 工程明細 | O6: 假設工程
A7: dazhan-002 | B7: 假設工程 | D7: A002 | E7: 甲種安全圍籬工程/含工程告 示牌 | F7: 式 | G7: 1 | H7: 733748 | I7: 733748 | J7: =IF(OR(G7="",H7=""),"",ROUND(G7*H7,0)) -> 733748 | K7: =IF(OR(I7="",J7=""),"",I7-J7) -> 0 | M7: 4 | N7: 工程明細 | O7: 假設工程
A8: dazhan-003 | B8: 假設工程 | D8: A003 | E8: 外管臨時水電申請及設備/施 工中水電使用費 | F8: 式 | G8: 1 | H8: 717000 | I8: 717000 | J8: =IF(OR(G8="",H8=""),"",ROUND(G8*H8,0)) -> 717000 | K8: =IF(OR(I8="",J8=""),"",I8-J8) -> 0 | M8: 4 | N8: 工程明細 | O8: 假設工程
A9: dazhan-004 | B9: 假設工程 | D9: A004 | E9: 施工臨時水電設備建置費 | F9: 式 | G9: 1 | H9: 360000 | I9: 360000 | J9: =IF(OR(G9="",H9=""),"",ROUND(G9*H9,0)) -> 360000 | K9: =IF(OR(I9="",J9=""),"",I9-J9) -> 0 | M9: 4 | N9: 工程明細 | O9: 假設工程
A10: dazhan-005 | B10: 假設工程 | D10: A005 | E10: 營建混合廢棄物證明及處理 費 | F10: 式 | G10: 1 | H10: 980100 | I10: 980100 | J10: =IF(OR(G10="",H10=""),"",ROUND(G10*H10,0)) -> 980100 | K10: =IF(OR(I10="",J10=""),"",I10-J10) -> 0 | M10: 4 | N10: 工程明細 | O10: 假設工程
A11: dazhan-006 | B11: 假設工程 | D11: A006 | E11: 公共排水溝及道路修復工程 | F11: 式 | G11: 1 | H11: 140000 | I11: 140000 | J11: =IF(OR(G11="",H11=""),"",ROUND(G11*H11,0)) -> 140000 | K11: =IF(OR(I11="",J11=""),"",I11-J11) -> 0 | M11: 4 | N11: 工程明細 | O11: 假設工程
A12: dazhan-007 | B12: 假設工程 | D12: A007 | E12: 工地保全費用/設備保全 | F12: 式 | G12: 1 | H12: 136200 | I12: 136200 | J12: =IF(OR(G12="",H12=""),"",ROUND(G12*H12,0)) -> 136200 | K12: =IF(OR(I12="",J12=""),"",I12-J12) -> 0 | M12: 4 | N12: 工程明細 | O12: 假設工程
A13: dazhan-008 | B13: 土方工程 | D13: B001 | E13: 現有圍籬、成功二路120巷入 口處鐵皮屋拆除運棄及整地 工程 | F13: 式 | G13: 1 | H13: 426000 | I13: 426000 | J13: =IF(OR(G13="",H13=""),"",ROUND(G13*H13,0)) -> 426000 | K13: =IF(OR(I13="",J13=""),"",I13-J13) -> 0 | M13: 5 | N13: 工程明細 | O13: 土方及結構工程
A14: dazhan-009 | B14: 土方工程 | D14: B002 | E14: 土方開挖 | F14: M3 | G14: 1421.46 | H14: 450 | I14: 639657 | J14: =IF(OR(G14="",H14=""),"",ROUND(G14*H14,0)) -> 639657 | K14: =IF(OR(I14="",J14=""),"",I14-J14) -> 0 | L14: 實方 | M14: 5 | N14: 工程明細 | O14: 土方及結構工程
A15: dazhan-010 | B15: 土方工程 | D15: B003 | E15: 回填土方 | F15: M3 | G15: 1421.46 | H15: 360 | I15: 511726 | J15: =IF(OR(G15="",H15=""),"",ROUND(G15*H15,0)) -> 511726 | K15: =IF(OR(I15="",J15=""),"",I15-J15) -> 0 | L15: 實方/暫置基地內 | M15: 5 | N15: 工程明細 | O15: 土方及結構工程
A16: dazhan-011 | B16: 土方工程 | D16: B004 | E16: 污水處理區土方開挖及回填 工程（二處） | F16: 式 | G16: 1 | H16: 60000 | I16: 60000 | J16: =IF(OR(G16="",H16=""),"",ROUND(G16*H16,0)) -> 60000 | K16: =IF(OR(I16="",J16=""),"",I16-J16) -> 0 | M16: 5 | N16: 工程明細 | O16: 土方及結構工程
A17: dazhan-012 | B17: 鋼構工程 | D17: C001 | E17: SN490B鋼構材料 H型鋼 | F17: 噸 | G17: 366.55 | H17: 31700 | I17: 11619635 | J17: =IF(OR(G17="",H17=""),"",ROUND(G17*H17,0)) -> 11619635 | K17: =IF(OR(I17="",J17=""),"",I17-J17) -> 0 | M17: 6 | N17: 工程明細 | O17: 鋼構工程
A18: dazhan-013 | B18: 鋼構工程 | D18: C002 | E18: SN490B鋼鈑材料 | F18: 噸 | G18: 76.21 | H18: 38200 | I18: 2911222 | J18: =IF(OR(G18="",H18=""),"",ROUND(G18*H18,0)) -> 2911222 | K18: =IF(OR(I18="",J18=""),"",I18-J18) -> 0 | M18: 6 | N18: 工程明細 | O18: 鋼構工程
A19: dazhan-014 | B19: 鋼構工程 | D19: C003 | E19: 廠內加工焊接（含柱封板） | F19: 噸 | G19: 442.76 | H19: 6800 | I19: 3010768 | J19: =IF(OR(G19="",H19=""),"",ROUND(G19*H19,0)) -> 3010768 | K19: =IF(OR(I19="",J19=""),"",I19-J19) -> 0 | M19: 6 | N19: 工程明細 | O19: 鋼構工程
A20: dazhan-015 | B20: 鋼構工程 | D20: C004 | E20: 鋼構噴砂+1道磷酸鋅底漆 | F20: 噸 | G20: 442.76 | H20: 2900 | I20: 1284004 | J20: =IF(OR(G20="",H20=""),"",ROUND(G20*H20,0)) -> 1284004 | K20: =IF(OR(I20="",J20=""),"",I20-J20) -> 0 | M20: 6 | N20: 工程明細 | O20: 鋼構工程
A21: dazhan-016 | B21: 鋼構工程 | D21: C005 | E21: 鋼構運輸 | F21: 噸 | G21: 442.76 | H21: 1700 | I21: 752692 | J21: =IF(OR(G21="",H21=""),"",ROUND(G21*H21,0)) -> 752692 | K21: =IF(OR(I21="",J21=""),"",I21-J21) -> 0 | M21: 6 | N21: 工程明細 | O21: 鋼構工程
A22: dazhan-017 | B22: 鋼構工程 | D22: C006 | E22: 鋼構加工損耗品/五金焊材 | F22: 噸 | G22: 442.76 | H22: 1500 | I22: 664140 | J22: =IF(OR(G22="",H22=""),"",ROUND(G22*H22,0)) -> 664140 | K22: =IF(OR(I22="",J22=""),"",I22-J22) -> 0 | M22: 6 | N22: 工程明細 | O22: 鋼構工程
A23: dazhan-018 | B23: 鋼構工程 | D23: C007 | E23: 鋼構組立吊裝 | F23: 噸 | G23: 442.76 | H23: 6000 | I23: 2656560 | J23: =IF(OR(G23="",H23=""),"",ROUND(G23*H23,0)) -> 2656560 | K23: =IF(OR(I23="",J23=""),"",I23-J23) -> 0 | M23: 6 | N23: 工程明細 | O23: 鋼構工程
A24: dazhan-019 | B24: 鋼構工程 | D24: C008 | E24: 高拉力螺栓 | F24: KG | G24: 4664 | H24: 88 | I24: 410432 | J24: =IF(OR(G24="",H24=""),"",ROUND(G24*H24,0)) -> 410432 | K24: =IF(OR(I24="",J24=""),"",I24-J24) -> 0 | M24: 6 | N24: 工程明細 | O24: 鋼構工程
A25: dazhan-020 | B25: 鋼構工程 | D25: C009 | E25: 鋼承版（3W DECK T=1.2mm） | F25: M2 | G25: 3867.65 | H25: 630 | I25: 2436620 | J25: =IF(OR(G25="",H25=""),"",ROUND(G25*H25,0)) -> 2436620 | K25: =IF(OR(I25="",J25=""),"",I25-J25) -> 0 | M25: 6 | N25: 工程明細 | O25: 鋼構工程
A26: dazhan-021 | B26: 鋼構工程 | D26: C010 | E26: DECK剪力釘（φ19*76L） | F26: 支 | G26: 14673 | H26: 32 | I26: 469536 | J26: =IF(OR(G26="",H26=""),"",ROUND(G26*H26,0)) -> 469536 | K26: =IF(OR(I26="",J26=""),"",I26-J26) -> 0 | M26: 6 | N26: 工程明細 | O26: 鋼構工程
A27: dazhan-022 | B27: 鋼構工程 | D27: C011 | E27: 與RC牆接合剪力釘 | F27: 支 | G27: 9344 | H27: 30 | I27: 280320 | J27: =IF(OR(G27="",H27=""),"",ROUND(G27*H27,0)) -> 280320 | K27: =IF(OR(I27="",J27=""),"",I27-J27) -> 0 | M27: 6 | N27: 工程明細 | O27: 鋼構工程
... A31: dazhan-026 | B31: 鋼構工程 | D31: C015 | E31: 鋼構無收縮水泥灌注 | F31: 處 | G31: 34 | H31: 4500 | I31: 153000 | J31: =IF(OR(G31="",H31=""),"",ROUND(G31*H31,0)) -> 153000 | K31: =IF(OR(I31="",J31=""),"",I31-J31) -> 0 | M31: 6 | N31: 工程明細 | O31: 鋼構工程
A32: dazhan-027 | B32: 鋼構工程 | D32: C016 | E32: 二工鋼構工程 | F32: KG | G32: 4982 | H32: 88 | I32: 438416 | J32: =IF(OR(G32="",H32=""),"",ROUND(G32*H32,0)) -> 438416 | K32: =IF(OR(I32="",J32=""),"",I32-J32) -> 0 | L32: （含廠製.噴砂油 漆.運輸.安裝） | M32: 6 | N32: 工程明細 | O32: 鋼構工程
A33: dazhan-028 | B33: 鋼構工程 | D33: C017 | E33: 二工鋼承版（3W T=1.2mm） | F33: M2 | G33: 144.2 | H33: 830 | I33: 119686 | J33: =IF(OR(G33="",H33=""),"",ROUND(G33*H33,0)) -> 119686 | K33: =IF(OR(I33="",J33=""),"",I33-J33) -> 0 | M33: 6 | N33: 工程明細 | O33: 鋼構工程
A34: dazhan-029 | B34: 鋼構工程 | D34: C018 | E34: 鋼構檢驗 | F34: 噸 | G34: 442.76 | H34: 650 | I34: 287794 | J34: =IF(OR(G34="",H34=""),"",ROUND(G34*H34,0)) -> 287794 | K34: =IF(OR(I34="",J34=""),"",I34-J34) -> 0 | M34: 6 | N34: 工程明細 | O34: 鋼構工程
A35: dazhan-030 | B35: 鋼構工程 | D35: C019 | E35: 鋼構施工圖繪製及安全措施 | F35: 噸 | G35: 442.76 | H35: 1200 | I35: 531312 | J35: =IF(OR(G35="",H35=""),"",ROUND(G35*H35,0)) -> 531312 | K35: =IF(OR(I35="",J35=""),"",I35-J35) -> 0 | M35: 6 | N35: 工程明細 | O35: 鋼構工程
A36: dazhan-031 | B36: 鋼構工程 | D36: C021 | E36: 鋼樑鋼筋焊植工程 | F36: 支 | G36: 4646 | H36: 30 | I36: 139380 | J36: =IF(OR(G36="",H36=""),"",ROUND(G36*H36,0)) -> 139380 | K36: =IF(OR(I36="",J36=""),"",I36-J36) -> 0 | M36: 6 | N36: 工程明細 | O36: 鋼構工程
A37: dazhan-032 | B37: 鋼構工程 | D37: C022 | E37: 鋼柱.鋼樑噴塗防火漆1小時 | F37: M2 | G37: 5731.95 | H37: 265 | I37: 1518967 | J37: =IF(OR(G37="",H37=""),"",ROUND(G37*H37,0)) -> 1518967 | K37: =IF(OR(I37="",J37=""),"",I37-J37) -> 0 | L37: （FM-906）+面漆 （1030FM | M37: 6 | N37: 工程明細 | O37: 鋼構工程
A38: dazhan-033 | B38: 鋼構工程 | D38: C023 | E38: 甲梯/噴塗及手工刷塗面漆 | F38: 座 | G38: 1 | H38: 32000 | I38: 32000 | J38: =IF(OR(G38="",H38=""),"",ROUND(G38*H38,0)) -> 32000 | K38: =IF(OR(I38="",J38=""),"",I38-J38) -> 0 | M38: 6 | N38: 工程明細 | O38: 鋼構工程
A39: dazhan-034 | B39: 鋼構工程 | D39: C024 | E39: 乙梯/噴塗及手工刷塗面漆 | F39: 座 | G39: 1 | H39: 46000 | I39: 46000 | J39: =IF(OR(G39="",H39=""),"",ROUND(G39*H39,0)) -> 46000 | K39: =IF(OR(I39="",J39=""),"",I39-J39) -> 0 | M39: 6 | N39: 工程明細 | O39: 鋼構工程
A40: dazhan-035 | B40: 鋼構工程 | D40: C025 | E40: 剪刀式高空作業車 | F40: 式 | G40: 1 | H40: 80000 | I40: 80000 | J40: =IF(OR(G40="",H40=""),"",ROUND(G40*H40,0)) -> 80000 | K40: =IF(OR(I40="",J40=""),"",I40-J40) -> 0 | L40: 4台 | M40: 6 | N40: 工程明細 | O40: 鋼構工程
A41: dazhan-036 | B41: 結構工程 | D41: D001 | E41: 鋼筋加工及組立SD280 #3 | F41: T | G41: 96.04 | H41: 27900 | I41: 2679516 | J41: =IF(OR(G41="",H41=""),"",ROUND(G41*H41,0)) -> 2679516 | K41: =IF(OR(I41="",J41=""),"",I41-J41) -> 0 | L41: 非水淬 | M41: 7 | N41: 工程明細 | O41: 土方及結構工程
A42: dazhan-037 | B42: 結構工程 | D42: D002 | E42: 鋼筋加工及組立 SD420W/#4（含）以上 | F42: T | G42: 252.07 | H42: 28700 | I42: 7234409 | J42: =IF(OR(G42="",H42=""),"",ROUND(G42*H42,0)) -> 7234409 | K42: =IF(OR(I42="",J42=""),"",I42-J42) -> 0 | M42: 7 | N42: 工程明細 | O42: 土方及結構工程
A43: dazhan-038 | B43: 結構工程 | D43: D003 | E43: 鋼梯點焊鋼絲網舖設工程 | F43: M2 | G43: 70.91 | H43: 306 | I43: 21698 | J43: =IF(OR(G43="",H43=""),"",ROUND(G43*H43,0)) -> 21698 | K43: =IF(OR(I43="",J43=""),"",I43-J43) -> 0 | M43: 7 | N43: 工程明細 | O43: 土方及結構工程
A44: dazhan-039 | B44: 結構工程 | D44: D004 | E44: 預拌混凝土及澆置 2000PSI | F44: M3 | G44: 286.35 | H44: 2940 | I44: 841869 | J44: =IF(OR(G44="",H44=""),"",ROUND(G44*H44,0)) -> 841869 | K44: =IF(OR(I44="",J44=""),"",I44-J44) -> 0 | L44: 台鋼 | M44: 7 | N44: 工程明細 | O44: 土方及結構工程
A45: dazhan-040 | B45: 結構工程 | D45: D005 | E45: 預拌混凝土及澆置 4000PSI | F45: M3 | G45: 2747.47 | H45: 3240 | I45: 8901803 | J45: =IF(OR(G45="",H45=""),"",ROUND(G45*H45,0)) -> 8901803 | K45: =IF(OR(I45="",J45=""),"",I45-J45) -> 0 | L45: 亞泥 | M45: 7 | N45: 工程明細 | O45: 土方及結構工程
...

Sheet 備註與來源
A2: 來源與報價條款
A5: PDF頁 | B5: 內容類型 | C5: 原文／整理說明
B6: 來源PDF | C6: 115.09.30-大展營造-工程估價書.pdf
B7: 提供文件頁數 | C7: 20
B8: 整理原則 | C8: 原複價為分析基礎；未列價不當零元；數量×單價僅供核對。
A9: 1 | B9: 原報價一般備註（掃描轉錄） | C9: 備註說明：
A10: 1 | B10: 原報價一般備註（掃描轉錄） | C10: 天營造股份有限公司
A11: 1 | B11: 原報價一般備註（掃描轉錄） | C11: 壹、本估價自報價日起7天內有效。
A12: 1 | B12: 原報價一般備註（掃描轉錄） | C12: * 115.9.30需
A13: 1 | B13: 原報價一般備註（掃描轉錄） | C13: 貳、報價單項目說明如下：
A14: 1 | B14: 原報價一般備註（掃描轉錄） | C14: 報價專用章
A15: 1 | B15: 原報價一般備註（掃描轉錄） | C15: 1、不含臨時水電申請外管線路費、空氣汙染防制費
A16: 1 | B16: 原報價一般備註（掃描轉錄） | C16: /待主管機關設定完成後由業主自理繳費。 | 估算成控
A17: 1 | B17: 原報價一般備註（掃描轉錄） | C17: 2、不含衛浴設備及承裝工程、安全維護設備及承裝工程、機電設備及承裝工程。
A18: 1 | B18: 原報價一般備註（掃描轉錄） | C18: 3、不含電梯設備及承裝工程（業主自理）/施工階段須無償提供營造借用電梯使用。
A19: 1 | B19: 原報價一般備註（掃描轉錄） | C19: 4、10人份污水處理設施採RC預鑄式報價（免另施作護體）
A20: 1 | B20: 原報價一般備註（掃描轉錄） | C20: 5、依建照綠化檢討區域留設戶外地坪（僅估列至整體粉光（刷毛）-無裝修材）、草皮、
... A75: 1 | B75: 文件與整理方式 | C75: PDF實際20頁，頁首標示共41頁；本次已整理提供的20頁，須確認是否尚有附件。 原始PDF保留；金額以原複價為準，乘算差額另列。
